Workbook

Sheet Instructions
A1: SupplierPulse - Supplier Performance & Procurement Analytics
A2: Procurement analysis workbook - author: Harjot Sandhu
A4: What this workbook does
A5: Evaluates supplier reliability, purchasing spend and procurement risk, and turns them into a prioritised action list.
A6: Two data sources - never mixed
A7: OBSERVED: City of Austin purchase-order lines, FY2022-FY2026 (1 Oct 2021 - 30 Sep 2026), from data.austintexas.gov. Supports spend, concentration, agreement coverage and like-for-like price analysis. It has no delivery dates.
A8: SYNTHETIC: a deterministic demonstration dataset of 14 anonymous suppliers (SUP-01 ... SUP-14), purchase orders and goods receipts. Used only to demonstrate delivery, quality, scorecard and scenario methods. Not real suppliers or real performance.
A9: Header colours
A10: Navy header = data loaded from the Python pipeline (values). Teal header = live Excel formula.
A11: Sheets
A12: Assumptions | B12: Inputs and thresholds used by every formula (yellow cells).
A13: Syn_Lines | B13: Synthetic PO lines (Excel table tblLines): loaded line facts + formula columns for due, on-time, in-full, OTIF, days late, lead time.
A14: Syn_Suppliers | B14: Synthetic supplier master and the designed behaviour of each supplier.
A15: Supplier_Summary | B15: Per-supplier delivery, quality, spend and PPV metrics (COUNTIFS / SUMIFS / AVERAGEIFS).
A16: Dependency | B16: Supplier spend share by category, main category and dependency tier.
A17: Scorecard | B17: Weighted 0-100 performance score, evidence status, competition rank, tier and action quadrant (XLOOKUP for names).
A18: Delivery_Trend | B18: Monthly OTIF by promised month.
A19: Exceptions | B19: Live supplier exception flags S1-S8 and the overdue-line list.
A20: Scenario | B20: A: volume reallocation model with inputs and sensitivity; B: OTIF-target scenario; C: observed price harmonisation.
A21: Austin_Vendors | B21: Observed vendor spend, share, cumulative share, rank and Pareto class (top 150 + aggregate).
A22: Austin_Categories | B22: Observed category spend, top-vendor share, HHI and dependency flags.
A23: Austin_Families | B23: Observed spend by family and fiscal year.
... A27: Validation | B27: Excel formulas reconciled against the Python pipeline.
A29: Testing note
A30: Formulas calculate when the file is opened (full recalculation on load). This workbook was generated with openpyxl and verified by recalculating it with the Python 'formulas' engine and comparing results with pandas and SQL; it has not been manually opened in Microsoft Excel by the author's build process.
A32: Modelled values (scenarios, price opportunity) are estimates under stated assumptions, not realised savings.

Sheet Assumptions
A1: Assumptions and thresholds
A2: Yellow cells are inputs. Every formula in the workbook reads its thresholds from this sheet.
B4: Assumption | C4: Value | D4: Used by / note
B5: Reporting (synthetic delivery data)
B6: As-of (reporting) date | C6: 46295 | D6: Lines promised after this date are not yet due
B7: On-time grace days | C7: 0 | D7: Days after promised date still counted on time
B8: In-full tolerance | C8: 0 | D8: 0% = full ordered quantity required
B9: Scorecard weights (must total 100%)
B10: Weight: OTIF | C10: 0.4
B11: Weight: quality (reject rate) | C11: 0.25
B12: Weight: lead-time consistency | C12: 0.2
B13: Weight: lateness (avg days late) | C13: 0.15
B14: Scorecard scaling (target = 100 points, poor = 0 points)
B15: OTIF target | C15: 0.95
B16: OTIF poor | C16: 0.7
B17: Reject rate target | C17: 0.005
B18: Reject rate poor | C18: 0.05
B19: Lead-time SD target (days) | C19: 2
B20: Lead-time SD poor (days) | C20: 7
B21: Avg days late target | C21: 0
B22: Avg days late poor | C22: 5
B23: Evidence and tiers
B24: Due lines needed to rank | C24: 30
B25: Due lines needed for a provisional score | C25: 10
B26: Completed lines needed for lead-time variability | C26: 20
B27: Tier: Preferred at or above | C27: 85
B28: Tier: Acceptable at or above | C28: 70
B29: Tier: Improvement needed at or above | C29: 55
B30: Exception thresholds
B31: Chronic late: OTIF below | C31: 0.8 | D31: S1
B32: Minimum due lines for rate-based flags | C32: 30 | D32: S1, S2, S4, S5
B33: Unstable lead time: SD at or above (days) | C33: 5 | D33: S3
B34: Incomplete deliveries: in-full below | C34: 0.9 | D34: S4
B35: Quality: reject rate at or above | C35: 0.02 | D35: S5
B36: Deterioration: OTIF drop of at least | C36: 0.1 | D36: S2
B37: PPV: paid above contract by at least | C37: 0.1 | D37: S6
B38: High dependency: category share at or above | C38: 0.6 | D38: S8
B39: High dependency: share of total at or above | C39: 0.15 | D39: S8
B40: Medium dependency: category share at or above | C40: 0.35
B41: Medium dependency: share of total at or above | C41: 0.08
...

Sheet Syn_Lines
A1: po_line_id | B1: po_id | C1: supplier_id | D1: category_id | E1: item_id | F1: order_date | G1: promised_date | H1: ordered_qty | I1: unit_price | J1: standard_price | K1: cancelled | L1: short_closed | M1: received_qty | N1: qty_by_promise | O1: rejected_qty | P1: first_receipt_date | Q1: completion_date | R1: last_receipt_or_close_date | S1: line_value | T1: standard_value | U1: due | V1: on_time | W1: in_full | X1: otif | Y1: complete | Z1: open | AA1: overdue | AB1: days_late | AC1: lead_time_days | AD1: lead_time_sq | AE1: open_value | AF1: due_period | AG1: due_month
A2: SPO-00001-1 | B2: SPO-00001 | C2: SUP-14 | D2: FLEET | E2: FLEET-05 | F2: 45566 | G2: 45580 | H2: 8 | I2: 161.89 | J2: 168 | K2: 0 | L2: 0 | M2: 8 | N2: 8 | O2: 0 | P2: 45578 | Q2: 45578 | R2: 45578 | S2: =H2*I2 | T2: =H2*J2 | U2: =IF(AND(K2=0,G2<=Assumptions!$C$6),1,0) | V2: =IF(U2=1,IF(M2>0,IF(P2<=G2+Assumptions!$C$7,1,0),0),0) | W2: =IF(AND(U2=1,M2>=H2*(1-Assumptions!$C$8)),1,0) | X2: =IF(AND(U2=1,N2>=H2*(1-Assumptions!$C$8)),1,0) | Y2: =IF(ISNUMBER(Q2),1,0) | Z2: =IF(AND(K2=0,L2=0,Y2=0),1,0) | AA2: =IF(AND(Z2=1,G2<Assumptions!$C$6),1,0) | AB2: =IF(U2=0,"",IF(Y2=1,MAX(0,Q2-G2),IF(L2=1,MAX(0,R2-G2),MAX(0,Assumptions!$C$6-G2)))) | AC2: =IF(Y2=1,Q2-F2,"") | AD2: =IF(Y2=1,AC2^2,"") | AE2: =IF(Z2=1,(H2-M2)*I2,0) | AF2: =IF(G2<EDATE(Assumptions!$C$6,-12)+1,"prior_12m","last_12m") | AG2: =DATE(YEAR(G2),MONTH(G2),1)
A3: SPO-00001-2 | B3: SPO-00001 | C3: SUP-14 | D3: FLEET | E3: FLEET-08 | F3: 45566 | G3: 45580 | H3: 267 | I3: 5.81 | J3: 6.4 | K3: 0 | L3: 0 | M3: 267 | N3: 267 | O3: 0 | P3: 45575 | Q3: 45575 | R3: 45575 | S3: =H3*I3 | T3: =H3*J3 | U3: =IF(AND(K3=0,G3<=Assumptions!$C$6),1,0) | V3: =IF(U3=1,IF(M3>0,IF(P3<=G3+Assumptions!$C$7,1,0),0),0) | W3: =IF(AND(U3=1,M3>=H3*(1-Assumptions!$C$8)),1,0) | X3: =IF(AND(U3=1,N3>=H3*(1-Assumptions!$C$8)),1,0) | Y3: =IF(ISNUMBER(Q3),1,0) | Z3: =IF(AND(K3=0,L3=0,Y3=0),1,0) | AA3: =IF(AND(Z3=1,G3<Assumptions!$C$6),1,0) | AB3: =IF(U3=0,"",IF(Y3=1,MAX(0,Q3-G3),IF(L3=1,MAX(0,R3-G3),MAX(0,Assumptions!$C$6-G3)))) | AC3: =IF(Y3=1,Q3-F3,"") | AD3: =IF(Y3=1,AC3^2,"") | AE3: =IF(Z3=1,(H3-M3)*I3,0) | AF3: =IF(G3<EDATE(Assumptions!$C$6,-12)+1,"prior_12m","last_12m") | AG3: =DATE(YEAR(G3),MONTH(G3),1)
A4: SPO-00002-1 | B4: SPO-00002 | C4: SUP-01 | D4: ELEC | E4: ELEC-02 | F4: 45566 | G4: 45584 | H4: 675 | I4: 4.25 | J4: 4.2 | K4: 0 | L4: 0 | M4: 675 | N4: 0 | O4: 0 | P4: 45586 | Q4: 45586 | R4: 45586 | S4: =H4*I4 | T4: =H4*J4 | U4: =IF(AND(K4=0,G4<=Assumptions!$C$6),1,0) | V4: =IF(U4=1,IF(M4>0,IF(P4<=G4+Assumptions!$C$7,1,0),0),0) | W4: =IF(AND(U4=1,M4>=H4*(1-Assumptions!$C$8)),1,0) | X4: =IF(AND(U4=1,N4>=H4*(1-Assumptions!$C$8)),1,0) | Y4: =IF(ISNUMBER(Q4),1,0) | Z4: =IF(AND(K4=0,L4=0,Y4=0),1,0) | AA4: =IF(AND(Z4=1,G4<Assumptions!$C$6),1,0) | AB4: =IF(U4=0,"",IF(Y4=1,MAX(0,Q4-G4),IF(L4=1,MAX(0,R4-G4),MAX(0,Assumptions!$C$6-G4)))) | AC4: =IF(Y4=1,Q4-F4,"") | AD4: =IF(Y4=1,AC4^2,"") | AE4: =IF(Z4=1,(H4-M4)*I4,0) | AF4: =IF(G4<EDATE(Assumptions!$C$6,-12)+1,"prior_12m","last_12m") | AG4: =DATE(YEAR(G4),MONTH(G4),1)
A5: SPO-00002-2 | B5: SPO-00002 | C5: SUP-01 | D5: ELEC | E5: ELEC-08 | F5: 45566 | G5: 45584 | H5: 121 | I5: 18.87 | J5: 18 | K5: 0 | L5: 0 | M5: 121 | N5: 121 | O5: 0 | P5: 45578 | Q5: 45578 | R5: 45578 | S5: =H5*I5 | T5: =H5*J5 | U5: =IF(AND(K5=0,G5<=Assumptions!$C$6),1,0) | V5: =IF(U5=1,IF(M5>0,IF(P5<=G5+Assumptions!$C$7,1,0),0),0) | W5: =IF(AND(U5=1,M5>=H5*(1-Assumptions!$C$8)),1,0) | X5: =IF(AND(U5=1,N5>=H5*(1-Assumptions!$C$8)),1,0) | Y5: =IF(ISNUMBER(Q5),1,0) | Z5: =IF(AND(K5=0,L5=0,Y5=0),1,0) | AA5: =IF(AND(Z5=1,G5<Assumptions!$C$6),1,0) | AB5: =IF(U5=0,"",IF(Y5=1,MAX(0,Q5-G5),IF(L5=1,MAX(0,R5-G5),MAX(0,Assumptions!$C$6-G5)))) | AC5: =IF(Y5=1,Q5-F5,"") | AD5: =IF(Y5=1,AC5^2,"") | AE5: =IF(Z5=1,(H5-M5)*I5,0) | AF5: =IF(G5<EDATE(Assumptions!$C$6,-12)+1,"prior_12m","last_12m") | AG5: =DATE(YEAR(G5),MONTH(G5),1)
A6: SPO-00002-3 | B6: SPO-00002 | C6: SUP-01 | D6: ELEC | E6: ELEC-07 | F6: 45566 | G6: 45584 | H6: 416 | I6: 10.12 | J6: 9.8 | K6: 0 | L6: 0 | M6: 416 | N6: 416 | O6: 0 | P6: 45584 | Q6: 45584 | R6: 45584 | S6: =H6*I6 | T6: =H6*J6 | U6: =IF(AND(K6=0,G6<=Assumptions!$C$6),1,0) | V6: =IF(U6=1,IF(M6>0,IF(P6<=G6+Assumptions!$C$7,1,0),0),0) | W6: =IF(AND(U6=1,M6>=H6*(1-Assumptions!$C$8)),1,0) | X6: =IF(AND(U6=1,N6>=H6*(1-Assumptions!$C$8)),1,0) | Y6: =IF(ISNUMBER(Q6),1,0) | Z6: =IF(AND(K6=0,L6=0,Y6=0),1,0) | AA6: =IF(AND(Z6=1,G6<Assumptions!$C$6),1,0) | AB6: =IF(U6=0,"",IF(Y6=1,MAX(0,Q6-G6),IF(L6=1,MAX(0,R6-G6),MAX(0,Assumptions!$C$6-G6)))) | AC6: =IF(Y6=1,Q6-F6,"") | AD6: =IF(Y6=1,AC6^2,"") | AE6: =IF(Z6=1,(H6-M6)*I6,0) | AF6: =IF(G6<EDATE(Assumptions!$C$6,-12)+1,"prior_12m","last_12m") | AG6: =DATE(YEAR(G6),MONTH(G6),1)
A7: SPO-00003-1 | B7: SPO-00003 | C7: SUP-09 | D7: CHEM | E7: CHEM-04 | F7: 45567 | G7: 45581 | H7: 4 | I7: 815.23 | J7: 820 | K7: 0 | L7: 0 | M7: 4 | N7: 4 | O7: 0 | P7: 45578 | Q7: 45578 | R7: 45578 | S7: =H7*I7 | T7: =H7*J7 | U7: =IF(AND(K7=0,G7<=Assumptions!$C$6),1,0) | V7: =IF(U7=1,IF(M7>0,IF(P7<=G7+Assumptions!$C$7,1,0),0),0) | W7: =IF(AND(U7=1,M7>=H7*(1-Assumptions!$C$8)),1,0) | X7: =IF(AND(U7=1,N7>=H7*(1-Assumptions!$C$8)),1,0) | Y7: =IF(ISNUMBER(Q7),1,0) | Z7: =IF(AND(K7=0,L7=0,Y7=0),1,0) | AA7: =IF(AND(Z7=1,G7<Assumptions!$C$6),1,0) | AB7: =IF(U7=0,"",IF(Y7=1,MAX(0,Q7-G7),IF(L7=1,MAX(0,R7-G7),MAX(0,Assumptions!$C$6-G7)))) | AC7: =IF(Y7=1,Q7-F7,"") | AD7: =IF(Y7=1,AC7^2,"") | AE7: =IF(Z7=1,(H7-M7)*I7,0) | AF7: =IF(G7<EDATE(Assumptions!$C$6,-12)+1,"prior_12m","last_12m") | AG7: =DATE(YEAR(G7),MONTH(G7),1)
A8: SPO-00003-2 | B8: SPO-00003 | C8: SUP-09 | D8: CHEM | E8: CHEM-05 | F8: 45567 | G8: 45581 | H8: 2 | I8: 967.79 | J8: 930 | K8: 0 | L8: 0 | M8: 2 | N8: 2 | O8: 0 | P8: 45580 | Q8: 45580 | R8: 45580 | S8: =H8*I8 | T8: =H8*J8 | U8: =IF(AND(K8=0,G8<=Assumptions!$C$6),1,0) | V8: =IF(U8=1,IF(M8>0,IF(P8<=G8+Assumptions!$C$7,1,0),0),0) | W8: =IF(AND(U8=1,M8>=H8*(1-Assumptions!$C$8)),1,0) | X8: =IF(AND(U8=1,N8>=H8*(1-Assumptions!$C$8)),1,0) | Y8: =IF(ISNUMBER(Q8),1,0) | Z8: =IF(AND(K8=0,L8=0,Y8=0),1,0) | AA8: =IF(AND(Z8=1,G8<Assumptions!$C$6),1,0) | AB8: =IF(U8=0,"",IF(Y8=1,MAX(0,Q8-G8),IF(L8=1,MAX(0,R8-G8),MAX(0,Assumptions!$C$6-G8)))) | AC8: =IF(Y8=1,Q8-F8,"") | AD8: =IF(Y8=1,AC8^2,"") | AE8: =IF(Z8=1,(H8-M8)*I8,0) | AF8: =IF(G8<EDATE(Assumptions!$C$6,-12)+1,"prior_12m","last_12m") | AG8: =DATE(YEAR(G8),MONTH(G8),1)
A9: SPO-00003-3 | B9: SPO-00003 | C9: SUP-09 | D9: CHEM | E9: CHEM-03 | F9: 45567 | G9: 45581 | H9: 4 | I9: 274.27 | J9: 265 | K9: 0 | L9: 0 | M9: 4 | N9: 4 | O9: 0 | P9: 45578 | Q9: 45578 | R9: 45578 | S9: =H9*I9 | T9: =H9*J9 | U9: =IF(AND(K9=0,G9<=Assumptions!$C$6),1,0) | V9: =IF(U9=1,IF(M9>0,IF(P9<=G9+Assumptions!$C$7,1,0),0),0) | W9: =IF(AND(U9=1,M9>=H9*(1-Assumptions!$C$8)),1,0) | X9: =IF(AND(U9=1,N9>=H9*(1-Assumptions!$C$8)),1,0) | Y9: =IF(ISNUMBER(Q9),1,0) | Z9: =IF(AND(K9=0,L9=0,Y9=0),1,0) | AA9: =IF(AND(Z9=1,G9<Assumptions!$C$6),1,0) | AB9: =IF(U9=0,"",IF(Y9=1,MAX(0,Q9-G9),IF(L9=1,MAX(0,R9-G9),MAX(0,Assumptions!$C$6-G9)))) | AC9: =IF(Y9=1,Q9-F9,"") | AD9: =IF(Y9=1,AC9^2,"") | AE9: =IF(Z9=1,(H9-M9)*I9,0) | AF9: =IF(G9<EDATE(Assumptions!$C$6,-12)+1,"prior_12m","last_12m") | AG9: =DATE(YEAR(G9),MONTH(G9),1)
A10: SPO-00004-1 | B10: SPO-00004 | C10: SUP-07 | D10: MRO | E10: MRO-02 | F10: 45567 | G10: 45577 | H10: 32 | I10: 39.84 | J10: 41 | K10: 0 | L10: 0 | M10: 32 | N10: 32 | O10: 0 | P10: 45576 | Q10: 45576 | R10: 45576 | S10: =H10*I10 | T10: =H10*J10 | U10: =IF(AND(K10=0,G10<=Assumptions!$C$6),1,0) | V10: =IF(U10=1,IF(M10>0,IF(P10<=G10+Assumptions!$C$7,1,0),0),0) | W10: =IF(AND(U10=1,M10>=H10*(1-Assumptions!$C$8)),1,0) | X10: =IF(AND(U10=1,N10>=H10*(1-Assumptions!$C$8)),1,0) | Y10: =IF(ISNUMBER(Q10),1,0) | Z10: =IF(AND(K10=0,L10=0,Y10=0),1,0) | AA10: =IF(AND(Z10=1,G10<Assumptions!$C$6),1,0) | AB10: =IF(U10=0,"",IF(Y10=1,MAX(0,Q10-G10),IF(L10=1,MAX(0,R10-G10),MAX(0,Assumptions!$C$6-G10)))) | AC10: =IF(Y10=1,Q10-F10,"") | AD10: =IF(Y10=1,AC10^2,"") | AE10: =IF(Z10=1,(H10-M10)*I10,0) | AF10: =IF(G10<EDATE(Assumptions!$C$6,-12)+1,"prior_12m","last_12m") | AG10: =DATE(YEAR(G10),MONTH(G10),1)
A11: SPO-00004-2 | B11: SPO-00004 | C11: SUP-07 | D11: MRO | E11: MRO-01 | F11: 45567 | G11: 45577 | H11: 26 | I11: 53.75 | J11: 52 | K11: 0 | L11: 0 | M11: 26 | N11: 26 | O11: 0 | P11: 45576 | Q11: 45576 | R11: 45576 | S11: =H11*I11 | T11: =H11*J11 | U11: =IF(AND(K11=0,G11<=Assumptions!$C$6),1,0) | V11: =IF(U11=1,IF(M11>0,IF(P11<=G11+Assumptions!$C$7,1,0),0),0) | W11: =IF(AND(U11=1,M11>=H11*(1-Assumptions!$C$8)),1,0) | X11: =IF(AND(U11=1,N11>=H11*(1-Assumptions!$C$8)),1,0) | Y11: =IF(ISNUMBER(Q11),1,0) | Z11: =IF(AND(K11=0,L11=0,Y11=0),1,0) | AA11: =IF(AND(Z11=1,G11<Assumptions!$C$6),1,0) | AB11: =IF(U11=0,"",IF(Y11=1,MAX(0,Q11-G11),IF(L11=1,MAX(0,R11-G11),MAX(0,Assumptions!$C$6-G11)))) | AC11: =IF(Y11=1,Q11-F11,"") | AD11: =IF(Y11=1,AC11^2,"") | AE11: =IF(Z11=1,(H11-M11)*I11,0) | AF11: =IF(G11<EDATE(Assumptions!$C$6,-12)+1,"prior_12m","last_12m") | AG11: =DATE(YEAR(G11),MONTH(G11),1)
A12: SPO-00004-3 | B12: SPO-00004 | C12: SUP-07 | D12: MRO | E12: MRO-06 | F12: 45567 | G12: 45577 | H12: 510 | I12: 6.09 | J12: 6.1 | K12: 0 | L12: 0 | M12: 510 | N12: 510 | O12: 0 | P12: 45572 | Q12: 45572 | R12: 45572 | S12: =H12*I12 | T12: =H12*J12 | U12: =IF(AND(K12=0,G12<=Assumptions!$C$6),1,0) | V12: =IF(U12=1,IF(M12>0,IF(P12<=G12+Assumptions!$C$7,1,0),0),0) | W12: =IF(AND(U12=1,M12>=H12*(1-Assumptions!$C$8)),1,0) | X12: =IF(AND(U12=1,N12>=H12*(1-Assumptions!$C$8)),1,0) | Y12: =IF(ISNUMBER(Q12),1,0) | Z12: =IF(AND(K12=0,L12=0,Y12=0),1,0) | AA12: =IF(AND(Z12=1,G12<Assumptions!$C$6),1,0) | AB12: =IF(U12=0,"",IF(Y12=1,MAX(0,Q12-G12),IF(L12=1,MAX(0,R12-G12),MAX(0,Assumptions!$C$6-G12)))) | AC12: =IF(Y12=1,Q12-F12,"") | AD12: =IF(Y12=1,AC12^2,"") | AE12: =IF(Z12=1,(H12-M12)*I12,0) | AF12: =IF(G12<EDATE(Assumptions!$C$6,-12)+1,"prior_12m","last_12m") | AG12: =DATE(YEAR(G12),MONTH(G12),1)
A13: SPO-00004-4 | B13: SPO-00004 | C13: SUP-07 | D13: MRO | E13: MRO-07 | F13: 45567 | G13: 45577 | H13: 157 | I13: 14.19 | J13: 14 | K13: 0 | L13: 1 | M13: 115 | N13: 115 | O13: 0 | P13: 45570 | R13: 45570 | S13: =H13*I13 | T13: =H13*J13 | U13: =IF(AND(K13=0,G13<=Assumptions!$C$6),1,0) | V13: =IF(U13=1,IF(M13>0,IF(P13<=G13+Assumptions!$C$7,1,0),0),0) | W13: =IF(AND(U13=1,M13>=H13*(1-Assumptions!$C$8)),1,0) | X13: =IF(AND(U13=1,N13>=H13*(1-Assumptions!$C$8)),1,0) | Y13: =IF(ISNUMBER(Q13),1,0) | Z13: =IF(AND(K13=0,L13=0,Y13=0),1,0) | AA13: =IF(AND(Z13=1,G13<Assumptions!$C$6),1,0) | AB13: =IF(U13=0,"",IF(Y13=1,MAX(0,Q13-G13),IF(L13=1,MAX(0,R13-G13),MAX(0,Assumptions!$C$6-G13)))) | AC13: =IF(Y13=1,Q13-F13,"") | AD13: =IF(Y13=1,AC13^2,"") | AE13: =IF(Z13=1,(H13-M13)*I13,0) | AF13: =IF(G13<EDATE(Assumptions!$C$6,-12)+1,"prior_12m","last_12m") | AG13: =DATE(YEAR(G13),MONTH(G13),1)
A14: SPO-00005-1 | B14: SPO-00005 | C14: SUP-09 | D14: CHEM | E14: CHEM-03 | F14: 45568 | G14: 45582 | H14: 6 | I14: 276.03 | J14: 265 | K14: 0 | L14: 0 | M14: 6 | N14: 6 | O14: 0 | P14: 45582 | Q14: 45582 | R14: 45582 | S14: =H14*I14 | T14: =H14*J14 | U14: =IF(AND(K14=0,G14<=Assumptions!$C$6),1,0) | V14: =IF(U14=1,IF(M14>0,IF(P14<=G14+Assumptions!$C$7,1,0),0),0) | W14: =IF(AND(U14=1,M14>=H14*(1-Assumptions!$C$8)),1,0) | X14: =IF(AND(U14=1,N14>=H14*(1-Assumptions!$C$8)),1,0) | Y14: =IF(ISNUMBER(Q14),1,0) | Z14: =IF(AND(K14=0,L14=0,Y14=0),1,0) | AA14: =IF(AND(Z14=1,G14<Assumptions!$C$6),1,0) | AB14: =IF(U14=0,"",IF(Y14=1,MAX(0,Q14-G14),IF(L14=1,MAX(0,R14-G14),MAX(0,Assumptions!$C$6-G14)))) | AC14: =IF(Y14=1,Q14-F14,"") | AD14: =IF(Y14=1,AC14^2,"") | AE14: =IF(Z14=1,(H14-M14)*I14,0) | AF14: =IF(G14<EDATE(Assumptions!$C$6,-12)+1,"prior_12m","last_12m") | AG14: =DATE(YEAR(G14),MONTH(G14),1)
A15: SPO-00005-2 | B15: SPO-00005 | C15: SUP-09 | D15: CHEM | E15: CHEM-01 | F15: 45568 | G15: 45582 | H15: 2 | I15: 680.98 | J15: 640 | K15: 0 | L15: 0 | M15: 2 | N15: 2 | O15: 0 | P15: 45580 | Q15: 45580 | R15: 45580 | S15: =H15*I15 | T15: =H15*J15 | U15: =IF(AND(K15=0,G15<=Assumptions!$C$6),1,0) | V15: =IF(U15=1,IF(M15>0,IF(P15<=G15+Assumptions!$C$7,1,0),0),0) | W15: =IF(AND(U15=1,M15>=H15*(1-Assumptions!$C$8)),1,0) | X15: =IF(AND(U15=1,N15>=H15*(1-Assumptions!$C$8)),1,0) | Y15: =IF(ISNUMBER(Q15),1,0) | Z15: =IF(AND(K15=0,L15=0,Y15=0),1,0) | AA15: =IF(AND(Z15=1,G15<Assumptions!$C$6),1,0) | AB15: =IF(U15=0,"",IF(Y15=1,MAX(0,Q15-G15),IF(L15=1,MAX(0,R15-G15),MAX(0,Assumptions!$C$6-G15)))) | AC15: =IF(Y15=1,Q15-F15,"") | AD15: =IF(Y15=1,AC15^2,"") | AE15: =IF(Z15=1,(H15-M15)*I15,0) | AF15: =IF(G15<EDATE(Assumptions!$C$6,-12)+1,"prior_12m","last_12m") | AG15: =DATE(YEAR(G15),MONTH(G15),1)
A16: SPO-00005-3 | B16: SPO-00005 | C16: SUP-09 | D16: CHEM | E16: CHEM-05 | F16: 45568 | G16: 45582 | H16: 2 | I16: 962.73 | J16: 930 | K16: 0 | L16: 0 | M16: 2 | N16: 2 | O16: 0 | P16: 45582 | Q16: 45582 | R16: 45582 | S16: =H16*I16 | T16: =H16*J16 | U16: =IF(AND(K16=0,G16<=Assumptions!$C$6),1,0) | V16: =IF(U16=1,IF(M16>0,IF(P16<=G16+Assumptions!$C$7,1,0),0),0) | W16: =IF(AND(U16=1,M16>=H16*(1-Assumptions!$C$8)),1,0) | X16: =IF(AND(U16=1,N16>=H16*(1-Assumptions!$C$8)),1,0) | Y16: =IF(ISNUMBER(Q16),1,0) | Z16: =IF(AND(K16=0,L16=0,Y16=0),1,0) | AA16: =IF(AND(Z16=1,G16<Assumptions!$C$6),1,0) | AB16: =IF(U16=0,"",IF(Y16=1,MAX(0,Q16-G16),IF(L16=1,MAX(0,R16-G16),MAX(0,Assumptions!$C$6-G16)))) | AC16: =IF(Y16=1,Q16-F16,"") | AD16: =IF(Y16=1,AC16^2,"") | AE16: =IF(Z16=1,(H16-M16)*I16,0) | AF16: =IF(G16<EDATE(Assumptions!$C$6,-12)+1,"prior_12m","last_12m") | AG16: =DATE(YEAR(G16),MONTH(G16),1)
A17: SPO-00006-1 | B17: SPO-00006 | C17: SUP-14 | D17: FLEET | E17: FLEET-08 | F17: 45569 | G17: 45583 | H17: 398 | I17: 6.45 | J17: 6.4 | K17: 0 | L17: 0 | M17: 398 | N17: 0 | O17: 0 | P17: 45584 | Q17: 45584 | R17: 45584 | S17: =H17*I17 | T17: =H17*J17 | U17: =IF(AND(K17=0,G17<=Assumptions!$C$6),1,0) | V17: =IF(U17=1,IF(M17>0,IF(P17<=G17+Assumptions!$C$7,1,0),0),0) | W17: =IF(AND(U17=1,M17>=H17*(1-Assumptions!$C$8)),1,0) | X17: =IF(AND(U17=1,N17>=H17*(1-Assumptions!$C$8)),1,0) | Y17: =IF(ISNUMBER(Q17),1,0) | Z17: =IF(AND(K17=0,L17=0,Y17=0),1,0) | AA17: =IF(AND(Z17=1,G17<Assumptions!$C$6),1,0) | AB17: =IF(U17=0,"",IF(Y17=1,MAX(0,Q17-G17),IF(L17=1,MAX(0,R17-G17),MAX(0,Assumptions!$C$6-G17)))) | AC17: =IF(Y17=1,Q17-F17,"") | AD17: =IF(Y17=1,AC17^2,"") | AE17: =IF(Z17=1,(H17-M17)*I17,0) | AF17: =IF(G17<EDATE(Assumptions!$C$6,-12)+1,"prior_12m","last_12m") | AG17: =DATE(YEAR(G17),MONTH(G17),1)
A18: SPO-00007-1 | B18: SPO-00007 | C18: SUP-08 | D18: MRO | E18: MRO-06 | F18: 45569 | G18: 45580 | H18: 486 | I18: 5.89 | J18: 6.1 | K18: 0 | L18: 0 | M18: 486 | N18: 486 | O18: 0 | P18: 45577 | Q18: 45577 | R18: 45577 | S18: =H18*I18 | T18: =H18*J18 | U18: =IF(AND(K18=0,G18<=Assumptions!$C$6),1,0) | V18: =IF(U18=1,IF(M18>0,IF(P18<=G18+Assumptions!$C$7,1,0),0),0) | W18: =IF(AND(U18=1,M18>=H18*(1-Assumptions!$C$8)),1,0) | X18: =IF(AND(U18=1,N18>=H18*(1-Assumptions!$C$8)),1,0) | Y18: =IF(ISNUMBER(Q18),1,0) | Z18: =IF(AND(K18=0,L18=0,Y18=0),1,0) | AA18: =IF(AND(Z18=1,G18<Assumptions!$C$6),1,0) | AB18: =IF(U18=0,"",IF(Y18=1,MAX(0,Q18-G18),IF(L18=1,MAX(0,R18-G18),MAX(0,Assumptions!$C$6-G18)))) | AC18: =IF(Y18=1,Q18-F18,"") | AD18: =IF(Y18=1,AC18^2,"") | AE18: =IF(Z18=1,(H18-M18)*I18,0) | AF18: =IF(G18<EDATE(Assumptions!$C$6,-12)+1,"prior_12m","last_12m") | AG18: =DATE(YEAR(G18),MONTH(G18),1)
A19: SPO-00008-1 | B19: SPO-00008 | C19: SUP-06 | D19: MRO | E19: MRO-03 | F19: 45569 | G19: 45577 | H19: 415 | I19: 8.59 | J19: 8.9 | K19: 0 | L19: 0 | M19: 415 | N19: 415 | O19: 0 | P19: 45576 | Q19: 45576 | R19: 45576 | S19: =H19*I19 | T19: =H19*J19 | U19: =IF(AND(K19=0,G19<=Assumptions!$C$6),1,0) | V19: =IF(U19=1,IF(M19>0,IF(P19<=G19+Assumptions!$C$7,1,0),0),0) | W19: =IF(AND(U19=1,M19>=H19*(1-Assumptions!$C$8)),1,0) | X19: =IF(AND(U19=1,N19>=H19*(1-Assumptions!$C$8)),1,0) | Y19: =IF(ISNUMBER(Q19),1,0) | Z19: =IF(AND(K19=0,L19=0,Y19=0),1,0) | AA19: =IF(AND(Z19=1,G19<Assumptions!$C$6),1,0) | AB19: =IF(U19=0,"",IF(Y19=1,MAX(0,Q19-G19),IF(L19=1,MAX(0,R19-G19),MAX(0,Assumptions!$C$6-G19)))) | AC19: =IF(Y19=1,Q19-F19,"") | AD19: =IF(Y19=1,AC19^2,"") | AE19: =IF(Z19=1,(H19-M19)*I19,0) | AF19: =IF(G19<EDATE(Assumptions!$C$6,-12)+1,"prior_12m","last_12m") | AG19: =DATE(YEAR(G19),MONTH(G19),1)
A20: SPO-00008-2 | B20: SPO-00008 | C20: SUP-06 | D20: MRO | E20: MRO-08 | F20: 45569 | G20: 45577 | H20: 344 | I20: 7.3 | J20: 7.2 | K20: 0 | L20: 0 | M20: 344 | N20: 344 | O20: 0 | P20: 45575 | Q20: 45575 | R20: 45575 | S20: =H20*I20 | T20: =H20*J20 | U20: =IF(AND(K20=0,G20<=Assumptions!$C$6),1,0) | V20: =IF(U20=1,IF(M20>0,IF(P20<=G20+Assumptions!$C$7,1,0),0),0) | W20: =IF(AND(U20=1,M20>=H20*(1-Assumptions!$C$8)),1,0) | X20: =IF(AND(U20=1,N20>=H20*(1-Assumptions!$C$8)),1,0) | Y20: =IF(ISNUMBER(Q20),1,0) | Z20: =IF(AND(K20=0,L20=0,Y20=0),1,0) | AA20: =IF(AND(Z20=1,G20<Assumptions!$C$6),1,0) | AB20: =IF(U20=0,"",IF(Y20=1,MAX(0,Q20-G20),IF(L20=1,MAX(0,R20-G20),MAX(0,Assumptions!$C$6-G20)))) | AC20: =IF(Y20=1,Q20-F20,"") | AD20: =IF(Y20=1,AC20^2,"") | AE20: =IF(Z20=1,(H20-M20)*I20,0) | AF20: =IF(G20<EDATE(Assumptions!$C$6,-12)+1,"prior_12m","last_12m") | AG20: =DATE(YEAR(G20),MONTH(G20),1)
A21: SPO-00009-1 | B21: SPO-00009 | C21: SUP-01 | D21: ELEC | E21: ELEC-03 | F21: 45569 | G21: 45587 | H21: 24 | I21: 100.42 | J21: 96 | K21: 0 | L21: 0 | M21: 24 | N21: 24 | O21: 0 | P21: 45586 | Q21: 45586 | R21: 45586 | S21: =H21*I21 | T21: =H21*J21 | U21: =IF(AND(K21=0,G21<=Assumptions!$C$6),1,0) | V21: =IF(U21=1,IF(M21>0,IF(P21<=G21+Assumptions!$C$7,1,0),0),0) | W21: =IF(AND(U21=1,M21>=H21*(1-Assumptions!$C$8)),1,0) | X21: =IF(AND(U21=1,N21>=H21*(1-Assumptions!$C$8)),1,0) | Y21: =IF(ISNUMBER(Q21),1,0) | Z21: =IF(AND(K21=0,L21=0,Y21=0),1,0) | AA21: =IF(AND(Z21=1,G21<Assumptions!$C$6),1,0) | AB21: =IF(U21=0,"",IF(Y21=1,MAX(0,Q21-G21),IF(L21=1,MAX(0,R21-G21),MAX(0,Assumptions!$C$6-G21)))) | AC21: =IF(Y21=1,Q21-F21,"") | AD21: =IF(Y21=1,AC21^2,"") | AE21: =IF(Z21=1,(H21-M21)*I21,0) | AF21: =IF(G21<EDATE(Assumptions!$C$6,-12)+1,"prior_12m","last_12m") | AG21: =DATE(YEAR(G21),MONTH(G21),1)
A22: SPO-00009-2 | B22: SPO-00009 | C22: SUP-01 | D22: ELEC | E22: ELEC-01 | F22: 45569 | G22: 45587 | H22: 56 | I22: 38.16 | J22: 38 | K22: 0 | L22: 0 | M22: 56 | N22: 56 | O22: 0 | P22: 45586 | Q22: 45586 | R22: 45586 | S22: =H22*I22 | T22: =H22*J22 | U22: =IF(AND(K22=0,G22<=Assumptions!$C$6),1,0) | V22: =IF(U22=1,IF(M22>0,IF(P22<=G22+Assumptions!$C$7,1,0),0),0) | W22: =IF(AND(U22=1,M22>=H22*(1-Assumptions!$C$8)),1,0) | X22: =IF(AND(U22=1,N22>=H22*(1-Assumptions!$C$8)),1,0) | Y22: =IF(ISNUMBER(Q22),1,0) | Z22: =IF(AND(K22=0,L22=0,Y22=0),1,0) | AA22: =IF(AND(Z22=1,G22<Assumptions!$C$6),1,0) | AB22: =IF(U22=0,"",IF(Y22=1,MAX(0,Q22-G22),IF(L22=1,MAX(0,R22-G22),MAX(0,Assumptions!$C$6-G22)))) | AC22: =IF(Y22=1,Q22-F22,"") | AD22: =IF(Y22=1,AC22^2,"") | AE22: =IF(Z22=1,(H22-M22)*I22,0) | AF22: =IF(G22<EDATE(Assumptions!$C$6,-12)+1,"prior_12m","last_12m") | AG22: =DATE(YEAR(G22),MONTH(G22),1)
A23: SPO-00009-3 | B23: SPO-00009 | C23: SUP-01 | D23: ELEC | E23: ELEC-06 | F23: 45569 | G23: 45587 | H23: 48 | I23: 153.53 | J23: 145 | K23: 0 | L23: 0 | M23: 48 | N23: 48 | O23: 0 | P23: 45583 | Q23: 45583 | R23: 45583 | S23: =H23*I23 | T23: =H23*J23 | U23: =IF(AND(K23=0,G23<=Assumptions!$C$6),1,0) | V23: =IF(U23=1,IF(M23>0,IF(P23<=G23+Assumptions!$C$7,1,0),0),0) | W23: =IF(AND(U23=1,M23>=H23*(1-Assumptions!$C$8)),1,0) | X23: =IF(AND(U23=1,N23>=H23*(1-Assumptions!$C$8)),1,0) | Y23: =IF(ISNUMBER(Q23),1,0) | Z23: =IF(AND(K23=0,L23=0,Y23=0),1,0) | AA23: =IF(AND(Z23=1,G23<Assumptions!$C$6),1,0) | AB23: =IF(U23=0,"",IF(Y23=1,MAX(0,Q23-G23),IF(L23=1,MAX(0,R23-G23),MAX(0,Assumptions!$C$6-G23)))) | AC23: =IF(Y23=1,Q23-F23,"") | AD23: =IF(Y23=1,AC23^2,"") | AE23: =IF(Z23=1,(H23-M23)*I23,0) | AF23: =IF(G23<EDATE(Assumptions!$C$6,-12)+1,"prior_12m","last_12m") | AG23: =DATE(YEAR(G23),MONTH(G23),1)
A24: SPO-00009-4 | B24: SPO-00009 | C24: SUP-01 | D24: ELEC | E24: ELEC-05 | F24: 45569 | G24: 45587 | H24: 234 | I24: 11.59 | J24: 11.5 | K24: 0 | L24: 0 | M24: 234 | N24: 234 | O24: 0 | P24: 45583 | Q24: 45583 | R24: 45583 | S24: =H24*I24 | T24: =H24*J24 | U24: =IF(AND(K24=0,G24<=Assumptions!$C$6),1,0) | V24: =IF(U24=1,IF(M24>0,IF(P24<=G24+Assumptions!$C$7,1,0),0),0) | W24: =IF(AND(U24=1,M24>=H24*(1-Assumptions!$C$8)),1,0) | X24: =IF(AND(U24=1,N24>=H24*(1-Assumptions!$C$8)),1,0) | Y24: =IF(ISNUMBER(Q24),1,0) | Z24: =IF(AND(K24=0,L24=0,Y24=0),1,0) | AA24: =IF(AND(Z24=1,G24<Assumptions!$C$6),1,0) | AB24: =IF(U24=0,"",IF(Y24=1,MAX(0,Q24-G24),IF(L24=1,MAX(0,R24-G24),MAX(0,Assumptions!$C$6-G24)))) | AC24: =IF(Y24=1,Q24-F24,"") | AD24: =IF(Y24=1,AC24^2,"") | AE24: =IF(Z24=1,(H24-M24)*I24,0) | AF24: =IF(G24<EDATE(Assumptions!$C$6,-12)+1,"prior_12m","last_12m") | AG24: =DATE(YEAR(G24),MONTH(G24),1)
A25: SPO-00010-1 | B25: SPO-00010 | C25: SUP-06 | D25: MRO | E25: MRO-03 | F25: 45569 | G25: 45577 | H25: 131 | I25: 8.72 | J25: 8.9 | K25: 0 | L25: 0 | M25: 131 | N25: 131 | O25: 0 | P25: 45574 | Q25: 45574 | R25: 45574 | S25: =H25*I25 | T25: =H25*J25 | U25: =IF(AND(K25=0,G25<=Assumptions!$C$6),1,0) | V25: =IF(U25=1,IF(M25>0,IF(P25<=G25+Assumptions!$C$7,1,0),0),0) | W25: =IF(AND(U25=1,M25>=H25*(1-Assumptions!$C$8)),1,0) | X25: =IF(AND(U25=1,N25>=H25*(1-Assumptions!$C$8)),1,0) | Y25: =IF(ISNUMBER(Q25),1,0) | Z25: =IF(AND(K25=0,L25=0,Y25=0),1,0) | AA25: =IF(AND(Z25=1,G25<Assumptions!$C$6),1,0) | AB25: =IF(U25=0,"",IF(Y25=1,MAX(0,Q25-G25),IF(L25=1,MAX(0,R25-G25),MAX(0,Assumptions!$C$6-G25)))) | AC25: =IF(Y25=1,Q25-F25,"") | AD25: =IF(Y25=1,AC25^2,"") | AE25: =IF(Z25=1,(H25-M25)*I25,0) | AF25: =IF(G25<EDATE(Assumptions!$C$6,-12)+1,"prior_12m","last_12m") | AG25: =DATE(YEAR(G25),MONTH(G25),1)
... A48: SPO-00022-3 | B48: SPO-00022 | C48: SUP-09 | D48: CHEM | E48: CHEM-05 | F48: 45571 | G48: 45585 | H48: 2 | I48: 984.25 | J48: 930 | K48: 0 | L48: 0 | M48: 2 | N48: 2 | O48: 0 | P48: 45583 | Q48: 45583 | R48: 45583 | S48: =H48*I48 | T48: =H48*J48 | U48: =IF(AND(K48=0,G48<=Assumptions!$C$6),1,0) | V48: =IF(U48=1,IF(M48>0,IF(P48<=G48+Assumptions!$C$7,1,0),0),0) | W48: =IF(AND(U48=1,M48>=H48*(1-Assumptions!$C$8)),1,0) | X48: =IF(AND(U48=1,N48>=H48*(1-Assumptions!$C$8)),1,0) | Y48: =IF(ISNUMBER(Q48),1,0) | Z48: =IF(AND(K48=0,L48=0,Y48=0),1,0) | AA48: =IF(AND(Z48=1,G48<Assumptions!$C$6),1,0) | AB48: =IF(U48=0,"",IF(Y48=1,MAX(0,Q48-G48),IF(L48=1,MAX(0,R48-G48),MAX(0,Assumptions!$C$6-G48)))) | AC48: =IF(Y48=1,Q48-F48,"") | AD48: =IF(Y48=1,AC48^2,"") | AE48: =IF(Z48=1,(H48-M48)*I48,0) | AF48: =IF(G48<EDATE(Assumptions!$C$6,-12)+1,"prior_12m","last_12m") | AG48: =DATE(YEAR(G48),MONTH(G48),1)
A49: SPO-00023-1 | B49: SPO-00023 | C49: SUP-05 | D49: FLEET | E49: FLEET-01 | F49: 45571 | G49: 45585 | H49: 44 | I49: 67.73 | J49: 64 | K49: 1 | L49: 0 | M49: 0 | N49: 0 | O49: 0 | S49: =H49*I49 | T49: =H49*J49 | U49: =IF(AND(K49=0,G49<=Assumptions!$C$6),1,0) | V49: =IF(U49=1,IF(M49>0,IF(P49<=G49+Assumptions!$C$7,1,0),0),0) | W49: =IF(AND(U49=1,M49>=H49*(1-Assumptions!$C$8)),1,0) | X49: =IF(AND(U49=1,N49>=H49*(1-Assumptions!$C$8)),1,0) | Y49: =IF(ISNUMBER(Q49),1,0) | Z49: =IF(AND(K49=0,L49=0,Y49=0),1,0) | AA49: =IF(AND(Z49=1,G49<Assumptions!$C$6),1,0) | AB49: =IF(U49=0,"",IF(Y49=1,MAX(0,Q49-G49),IF(L49=1,MAX(0,R49-G49),MAX(0,Assumptions!$C$6-G49)))) | AC49: =IF(Y49=1,Q49-F49,"") | AD49: =IF(Y49=1,AC49^2,"") | AE49: =IF(Z49=1,(H49-M49)*I49,0) | AF49: =IF(G49<EDATE(Assumptions!$C$6,-12)+1,"prior_12m","last_12m") | AG49: =DATE(YEAR(G49),MONTH(G49),1)
A50: SPO-00023-2 | B50: SPO-00023 | C50: SUP-05 | D50: FLEET | E50: FLEET-03 | F50: 45571 | G50: 45585 | H50: 35 | I50: 21.3 | J50: 21 | K50: 0 | L50: 0 | M50: 35 | N50: 35 | O50: 0 | P50: 45581 | Q50: 45581 | R50: 45581 | S50: =H50*I50 | T50: =H50*J50 | U50: =IF(AND(K50=0,G50<=Assumptions!$C$6),1,0) | V50: =IF(U50=1,IF(M50>0,IF(P50<=G50+Assumptions!$C$7,1,0),0),0) | W50: =IF(AND(U50=1,M50>=H50*(1-Assumptions!$C$8)),1,0) | X50: =IF(AND(U50=1,N50>=H50*(1-Assumptions!$C$8)),1,0) | Y50: =IF(ISNUMBER(Q50),1,0) | Z50: =IF(AND(K50=0,L50=0,Y50=0),1,0) | AA50: =IF(AND(Z50=1,G50<Assumptions!$C$6),1,0) | AB50: =IF(U50=0,"",IF(Y50=1,MAX(0,Q50-G50),IF(L50=1,MAX(0,R50-G50),MAX(0,Assumptions!$C$6-G50)))) | AC50: =IF(Y50=1,Q50-F50,"") | AD50: =IF(Y50=1,AC50^2,"") | AE50: =IF(Z50=1,(H50-M50)*I50,0) | AF50: =IF(G50<EDATE(Assumptions!$C$6,-12)+1,"prior_12m","last_12m") | AG50: =DATE(YEAR(G50),MONTH(G50),1)
A51: SPO-00023-3 | B51: SPO-00023 | C51: SUP-05 | D51: FLEET | E51: FLEET-06 | F51: 45571 | G51: 45585 | H51: 36 | I51: 31.73 | J51: 33 | K51: 0 | L51: 0 | M51: 36 | N51: 36 | O51: 0 | P51: 45583 | Q51: 45583 | R51: 45583 | S51: =H51*I51 | T51: =H51*J51 | U51: =IF(AND(K51=0,G51<=Assumptions!$C$6),1,0) | V51: =IF(U51=1,IF(M51>0,IF(P51<=G51+Assumptions!$C$7,1,0),0),0) | W51: =IF(AND(U51=1,M51>=H51*(1-Assumptions!$C$8)),1,0) | X51: =IF(AND(U51=1,N51>=H51*(1-Assumptions!$C$8)),1,0) | Y51: =IF(ISNUMBER(Q51),1,0) | Z51: =IF(AND(K51=0,L51=0,Y51=0),1,0) | AA51: =IF(AND(Z51=1,G51<Assumptions!$C$6),1,0) | AB51: =IF(U51=0,"",IF(Y51=1,MAX(0,Q51-G51),IF(L51=1,MAX(0,R51-G51),MAX(0,Assumptions!$C$6-G51)))) | AC51: =IF(Y51=1,Q51-F51,"") | AD51: =IF(Y51=1,AC51^2,"") | AE51: =IF(Z51=1,(H51-M51)*I51,0) | AF51: =IF(G51<EDATE(Assumptions!$C$6,-12)+1,"prior_12m","last_12m") | AG51: =DATE(YEAR(G51),MONTH(G51),1)
A52: SPO-00023-4 | B52: SPO-00023 | C52: SUP-05 | D52: FLEET | E52: FLEET-08 | F52: 45571 | G52: 45585 | H52: 175 | I52: 6.58 | J52: 6.4 | K52: 0 | L52: 0 | M52: 175 | N52: 175 | O52: 0 | P52: 45583 | Q52: 45583 | R52: 45583 | S52: =H52*I52 | T52: =H52*J52 | U52: =IF(AND(K52=0,G52<=Assumptions!$C$6),1,0) | V52: =IF(U52=1,IF(M52>0,IF(P52<=G52+Assumptions!$C$7,1,0),0),0) | W52: =IF(AND(U52=1,M52>=H52*(1-Assumptions!$C$8)),1,0) | X52: =IF(AND(U52=1,N52>=H52*(1-Assumptions!$C$8)),1,0) | Y52: =IF(ISNUMBER(Q52),1,0) | Z52: =IF(AND(K52=0,L52=0,Y52=0),1,0) | AA52: =IF(AND(Z52=1,G52<Assumptions!$C$6),1,0) | AB52: =IF(U52=0,"",IF(Y52=1,MAX(0,Q52-G52),IF(L52=1,MAX(0,R52-G52),MAX(0,Assumptions!$C$6-G52)))) | AC52: =IF(Y52=1,Q52-F52,"") | AD52: =IF(Y52=1,AC52^2,"") | AE52: =IF(Z52=1,(H52-M52)*I52,0) | AF52: =IF(G52<EDATE(Assumptions!$C$6,-12)+1,"prior_12m","last_12m") | AG52: =DATE(YEAR(G52),MONTH(G52),1)
A53: SPO-00024-1 | B53: SPO-00024 | C53: SUP-04 | D53: FLEET | E53: FLEET-06 | F53: 45571 | G53: 45584 | H53: 38 | I53: 31.84 | J53: 33 | K53: 0 | L53: 0 | M53: 38 | N53: 0 | O53: 0 | P53: 45728 | Q53: 45728 | R53: 45728 | S53: =H53*I53 | T53: =H53*J53 | U53: =IF(AND(K53=0,G53<=Assumptions!$C$6),1,0) | V53: =IF(U53=1,IF(M53>0,IF(P53<=G53+Assumptions!$C$7,1,0),0),0) | W53: =IF(AND(U53=1,M53>=H53*(1-Assumptions!$C$8)),1,0) | X53: =IF(AND(U53=1,N53>=H53*(1-Assumptions!$C$8)),1,0) | Y53: =IF(ISNUMBER(Q53),1,0) | Z53: =IF(AND(K53=0,L53=0,Y53=0),1,0) | AA53: =IF(AND(Z53=1,G53<Assumptions!$C$6),1,0) | AB53: =IF(U53=0,"",IF(Y53=1,MAX(0,Q53-G53),IF(L53=1,MAX(0,R53-G53),MAX(0,Assumptions!$C$6-G53)))) | AC53: =IF(Y53=1,Q53-F53,"") | AD53: =IF(Y53=1,AC53^2,"") | AE53: =IF(Z53=1,(H53-M53)*I53,0) | AF53: =IF(G53<EDATE(Assumptions!$C$6,-12)+1,"prior_12m","last_12m") | AG53: =DATE(YEAR(G53),MONTH(G53),1)
A54: SPO-00024-2 | B54: SPO-00024 | C54: SUP-04 | D54: FLEET | E54: FLEET-05 | F54: 45571 | G54: 45584 | H54: 4 | I54: 161.58 | J54: 168 | K54: 0 | L54: 0 | M54: 4 | N54: 4 | O54: 0 | P54: 45577 | Q54: 45582 | R54: 45582 | S54: =H54*I54 | T54: =H54*J54 | U54: =IF(AND(K54=0,G54<=Assumptions!$C$6),1,0) | V54: =IF(U54=1,IF(M54>0,IF(P54<=G54+Assumptions!$C$7,1,0),0),0) | W54: =IF(AND(U54=1,M54>=H54*(1-Assumptions!$C$8)),1,0) | X54: =IF(AND(U54=1,N54>=H54*(1-Assumptions!$C$8)),1,0) | Y54: =IF(ISNUMBER(Q54),1,0) | Z54: =IF(AND(K54=0,L54=0,Y54=0),1,0) | AA54: =IF(AND(Z54=1,G54<Assumptions!$C$6),1,0) | AB54: =IF(U54=0,"",IF(Y54=1,MAX(0,Q54-G54),IF(L54=1,MAX(0,R54-G54),MAX(0,Assumptions!$C$6-G54)))) | AC54: =IF(Y54=1,Q54-F54,"") | AD54: =IF(Y54=1,AC54^2,"") | AE54: =IF(Z54=1,(H54-M54)*I54,0) | AF54: =IF(G54<EDATE(Assumptions!$C$6,-12)+1,"prior_12m","last_12m") | AG54: =DATE(YEAR(G54),MONTH(G54),1)
A55: SPO-00025-1 | B55: SPO-00025 | C55: SUP-01 | D55: ELEC | E55: ELEC-06 | F55: 45571 | G55: 45589 | H55: 19 | I55: 147 | J55: 145 | K55: 0 | L55: 0 | M55: 19 | N55: 19 | O55: 0 | P55: 45588 | Q55: 45588 | R55: 45588 | S55: =H55*I55 | T55: =H55*J55 | U55: =IF(AND(K55=0,G55<=Assumptions!$C$6),1,0) | V55: =IF(U55=1,IF(M55>0,IF(P55<=G55+Assumptions!$C$7,1,0),0),0) | W55: =IF(AND(U55=1,M55>=H55*(1-Assumptions!$C$8)),1,0) | X55: =IF(AND(U55=1,N55>=H55*(1-Assumptions!$C$8)),1,0) | Y55: =IF(ISNUMBER(Q55),1,0) | Z55: =IF(AND(K55=0,L55=0,Y55=0),1,0) | AA55: =IF(AND(Z55=1,G55<Assumptions!$C$6),1,0) | AB55: =IF(U55=0,"",IF(Y55=1,MAX(0,Q55-G55),IF(L55=1,MAX(0,R55-G55),MAX(0,Assumptions!$C$6-G55)))) | AC55: =IF(Y55=1,Q55-F55,"") | AD55: =IF(Y55=1,AC55^2,"") | AE55: =IF(Z55=1,(H55-M55)*I55,0) | AF55: =IF(G55<EDATE(Assumptions!$C$6,-12)+1,"prior_12m","last_12m") | AG55: =DATE(YEAR(G55),MONTH(G55),1)
A56: SPO-00026-1 | B56: SPO-00026 | C56: SUP-06 | D56: MRO | E56: MRO-06 | F56: 45571 | G56: 45579 | H56: 183 | I56: 5.83 | J56: 6.1 | K56: 0 | L56: 0 | M56: 183 | N56: 183 | O56: 0 | P56: 45576 | Q56: 45576 | R56: 45576 | S56: =H56*I56 | T56: =H56*J56 | U56: =IF(AND(K56=0,G56<=Assumptions!$C$6),1,0) | V56: =IF(U56=1,IF(M56>0,IF(P56<=G56+Assumptions!$C$7,1,0),0),0) | W56: =IF(AND(U56=1,M56>=H56*(1-Assumptions!$C$8)),1,0) | X56: =IF(AND(U56=1,N56>=H56*(1-Assumptions!$C$8)),1,0) | Y56: =IF(ISNUMBER(Q56),1,0) | Z56: =IF(AND(K56=0,L56=0,Y56=0),1,0) | AA56: =IF(AND(Z56=1,G56<Assumptions!$C$6),1,0) | AB56: =IF(U56=0,"",IF(Y56=1,MAX(0,Q56-G56),IF(L56=1,MAX(0,R56-G56),MAX(0,Assumptions!$C$6-G56)))) | AC56: =IF(Y56=1,Q56-F56,"") | AD56: =IF(Y56=1,AC56^2,"") | AE56: =IF(Z56=1,(H56-M56)*I56,0) | AF56: =IF(G56<EDATE(Assumptions!$C$6,-12)+1,"prior_12m","last_12m") | AG56: =DATE(YEAR(G56),MONTH(G56),1)
A57: SPO-00026-2 | B57: SPO-00026 | C57: SUP-06 | D57: MRO | E57: MRO-03 | F57: 45571 | G57: 45579 | H57: 153 | I57: 8.81 | J57: 8.9 | K57: 0 | L57: 0 | M57: 153 | N57: 153 | O57: 0 | P57: 45575 | Q57: 45575 | R57: 45575 | S57: =H57*I57 | T57: =H57*J57 | U57: =IF(AND(K57=0,G57<=Assumptions!$C$6),1,0) | V57: =IF(U57=1,IF(M57>0,IF(P57<=G57+Assumptions!$C$7,1,0),0),0) | W57: =IF(AND(U57=1,M57>=H57*(1-Assumptions!$C$8)),1,0) | X57: =IF(AND(U57=1,N57>=H57*(1-Assumptions!$C$8)),1,0) | Y57: =IF(ISNUMBER(Q57),1,0) | Z57: =IF(AND(K57=0,L57=0,Y57=0),1,0) | AA57: =IF(AND(Z57=1,G57<Assumptions!$C$6),1,0) | AB57: =IF(U57=0,"",IF(Y57=1,MAX(0,Q57-G57),IF(L57=1,MAX(0,R57-G57),MAX(0,Assumptions!$C$6-G57)))) | AC57: =IF(Y57=1,Q57-F57,"") | AD57: =IF(Y57=1,AC57^2,"") | AE57: =IF(Z57=1,(H57-M57)*I57,0) | AF57: =IF(G57<EDATE(Assumptions!$C$6,-12)+1,"prior_12m","last_12m") | AG57: =DATE(YEAR(G57),MONTH(G57),1)
A58: SPO-00026-3 | B58: SPO-00026 | C58: SUP-06 | D58: MRO | E58: MRO-01 | F58: 45571 | G58: 45579 | H58: 53 | I58: 51.36 | J58: 52 | K58: 0 | L58: 0 | M58: 53 | N58: 53 | O58: 0 | P58: 45577 | Q58: 45577 | R58: 45577 | S58: =H58*I58 | T58: =H58*J58 | U58: =IF(AND(K58=0,G58<=Assumptions!$C$6),1,0) | V58: =IF(U58=1,IF(M58>0,IF(P58<=G58+Assumptions!$C$7,1,0),0),0) | W58: =IF(AND(U58=1,M58>=H58*(1-Assumptions!$C$8)),1,0) | X58: =IF(AND(U58=1,N58>=H58*(1-Assumptions!$C$8)),1,0) | Y58: =IF(ISNUMBER(Q58),1,0) | Z58: =IF(AND(K58=0,L58=0,Y58=0),1,0) | AA58: =IF(AND(Z58=1,G58<Assumptions!$C$6),1,0) | AB58: =IF(U58=0,"",IF(Y58=1,MAX(0,Q58-G58),IF(L58=1,MAX(0,R58-G58),MAX(0,Assumptions!$C$6-G58)))) | AC58: =IF(Y58=1,Q58-F58,"") | AD58: =IF(Y58=1,AC58^2,"") | AE58: =IF(Z58=1,(H58-M58)*I58,0) | AF58: =IF(G58<EDATE(Assumptions!$C$6,-12)+1,"prior_12m","last_12m") | AG58: =DATE(YEAR(G58),MONTH(G58),1)
A59: SPO-00027-1 | B59: SPO-00027 | C59: SUP-01 | D59: ELEC | E59: ELEC-04 | F59: 45572 | G59: 45590 | H59: 40 | I59: 72.7 | J59: 72 | K59: 0 | L59: 0 | M59: 40 | N59: 40 | O59: 0 | P59: 45585 | Q59: 45585 | R59: 45585 | S59: =H59*I59 | T59: =H59*J59 | U59: =IF(AND(K59=0,G59<=Assumptions!$C$6),1,0) | V59: =IF(U59=1,IF(M59>0,IF(P59<=G59+Assumptions!$C$7,1,0),0),0) | W59: =IF(AND(U59=1,M59>=H59*(1-Assumptions!$C$8)),1,0) | X59: =IF(AND(U59=1,N59>=H59*(1-Assumptions!$C$8)),1,0) | Y59: =IF(ISNUMBER(Q59),1,0) | Z59: =IF(AND(K59=0,L59=0,Y59=0),1,0) | AA59: =IF(AND(Z59=1,G59<Assumptions!$C$6),1,0) | AB59: =IF(U59=0,"",IF(Y59=1,MAX(0,Q59-G59),IF(L59=1,MAX(0,R59-G59),MAX(0,Assumptions!$C$6-G59)))) | AC59: =IF(Y59=1,Q59-F59,"") | AD59: =IF(Y59=1,AC59^2,"") | AE59: =IF(Z59=1,(H59-M59)*I59,0) | AF59: =IF(G59<EDATE(Assumptions!$C$6,-12)+1,"prior_12m","last_12m") | AG59: =DATE(YEAR(G59),MONTH(G59),1)
A60: SPO-00028-1 | B60: SPO-00028 | C60: SUP-10 | D60: PPE | E60: PPE-05 | F60: 45572 | G60: 45585 | H60: 189 | I60: 10.92 | J60: 11 | K60: 0 | L60: 0 | M60: 189 | N60: 89 | O60: 0 | P60: 45582 | Q60: 45590 | R60: 45590 | S60: =H60*I60 | T60: =H60*J60 | U60: =IF(AND(K60=0,G60<=Assumptions!$C$6),1,0) | V60: =IF(U60=1,IF(M60>0,IF(P60<=G60+Assumptions!$C$7,1,0),0),0) | W60: =IF(AND(U60=1,M60>=H60*(1-Assumptions!$C$8)),1,0) | X60: =IF(AND(U60=1,N60>=H60*(1-Assumptions!$C$8)),1,0) | Y60: =IF(ISNUMBER(Q60),1,0) | Z60: =IF(AND(K60=0,L60=0,Y60=0),1,0) | AA60: =IF(AND(Z60=1,G60<Assumptions!$C$6),1,0) | AB60: =IF(U60=0,"",IF(Y60=1,MAX(0,Q60-G60),IF(L60=1,MAX(0,R60-G60),MAX(0,Assumptions!$C$6-G60)))) | AC60: =IF(Y60=1,Q60-F60,"") | AD60: =IF(Y60=1,AC60^2,"") | AE60: =IF(Z60=1,(H60-M60)*I60,0) | AF60: =IF(G60<EDATE(Assumptions!$C$6,-12)+1,"prior_12m","last_12m") | AG60: =DATE(YEAR(G60),MONTH(G60),1)
A61: SPO-00029-1 | B61: SPO-00029 | C61: SUP-01 | D61: ELEC | E61: ELEC-04 | F61: 45573 | G61: 45591 | H61: 73 | I61: 69.24 | J61: 72 | K61: 0 | L61: 0 | M61: 73 | N61: 73 | O61: 0 | P61: 45585 | Q61: 45585 | R61: 45585 | S61: =H61*I61 | T61: =H61*J61 | U61: =IF(AND(K61=0,G61<=Assumptions!$C$6),1,0) | V61: =IF(U61=1,IF(M61>0,IF(P61<=G61+Assumptions!$C$7,1,0),0),0) | W61: =IF(AND(U61=1,M61>=H61*(1-Assumptions!$C$8)),1,0) | X61: =IF(AND(U61=1,N61>=H61*(1-Assumptions!$C$8)),1,0) | Y61: =IF(ISNUMBER(Q61),1,0) | Z61: =IF(AND(K61=0,L61=0,Y61=0),1,0) | AA61: =IF(AND(Z61=1,G61<Assumptions!$C$6),1,0) | AB61: =IF(U61=0,"",IF(Y61=1,MAX(0,Q61-G61),IF(L61=1,MAX(0,R61-G61),MAX(0,Assumptions!$C$6-G61)))) | AC61: =IF(Y61=1,Q61-F61,"") | AD61: =IF(Y61=1,AC61^2,"") | AE61: =IF(Z61=1,(H61-M61)*I61,0) | AF61: =IF(G61<EDATE(Assumptions!$C$6,-12)+1,"prior_12m","last_12m") | AG61: =DATE(YEAR(G61),MONTH(G61),1)
A62: SPO-00029-2 | B62: SPO-00029 | C62: SUP-01 | D62: ELEC | E62: ELEC-05 | F62: 45573 | G62: 45591 | H62: 402 | I62: 11.87 | J62: 11.5 | K62: 1 | L62: 0 | M62: 0 | N62: 0 | O62: 0 | S62: =H62*I62 | T62: =H62*J62 | U62: =IF(AND(K62=0,G62<=Assumptions!$C$6),1,0) | V62: =IF(U62=1,IF(M62>0,IF(P62<=G62+Assumptions!$C$7,1,0),0),0) | W62: =IF(AND(U62=1,M62>=H62*(1-Assumptions!$C$8)),1,0) | X62: =IF(AND(U62=1,N62>=H62*(1-Assumptions!$C$8)),1,0) | Y62: =IF(ISNUMBER(Q62),1,0) | Z62: =IF(AND(K62=0,L62=0,Y62=0),1,0) | AA62: =IF(AND(Z62=1,G62<Assumptions!$C$6),1,0) | AB62: =IF(U62=0,"",IF(Y62=1,MAX(0,Q62-G62),IF(L62=1,MAX(0,R62-G62),MAX(0,Assumptions!$C$6-G62)))) | AC62: =IF(Y62=1,Q62-F62,"") | AD62: =IF(Y62=1,AC62^2,"") | AE62: =IF(Z62=1,(H62-M62)*I62,0) | AF62: =IF(G62<EDATE(Assumptions!$C$6,-12)+1,"prior_12m","last_12m") | AG62: =DATE(YEAR(G62),MONTH(G62),1)
...

Sheet Syn_Suppliers
A1: Synthetic supplier master
A2: SYNTHETIC DEMONSTRATION DATA - not real suppliers or real performance
A4: supplier_id | B4: supplier_name | C4: primary_category_id | D4: categories_served | E4: design_note
A5: SUP-01 | B5: Synthetic Supplier 01 | C5: ELEC | D5: ELEC | E5: Largest electrical supplier; delivery deteriorates in year 2
A6: SUP-02 | B6: Synthetic Supplier 02 | C6: ELEC | D6: ELEC | E6: Reliable electrical alternative with spare share
A7: SUP-03 | B7: Synthetic Supplier 03 | C7: ELEC | D7: ELEC | E7: Very few orders: tests the insufficient-evidence rule
A8: SUP-04 | B8: Synthetic Supplier 04 | C8: FLEET | D8: FLEET | E8: Chronically late fleet supplier with unstable lead times
A9: SUP-05 | B9: Synthetic Supplier 05 | C9: FLEET | D9: FLEET | E9: Reliable fleet supplier
A10: SUP-06 | B10: Synthetic Supplier 06 | C10: MRO | D10: MRO | E10: Excellent MRO supplier holding a large category share
A11: SUP-07 | B11: Synthetic Supplier 07 | C11: MRO | D11: MRO | E11: Frequent split and short shipments
A12: SUP-08 | B12: Synthetic Supplier 08 | C12: MRO | D12: MRO, PPE | E12: Generalist serving MRO and PPE
A13: SUP-09 | B13: Synthetic Supplier 09 | C13: CHEM | D13: CHEM | E13: Sole source for water treatment chemicals: good performance, high dependency
A14: SUP-10 | B14: Synthetic Supplier 10 | C14: PPE | D14: PPE | E14: Low price but recurring quality rejections
A15: SUP-11 | B15: Synthetic Supplier 11 | C15: PPE | D15: PPE | E15: Reliable PPE supplier
... A18: SUP-14 | B18: Synthetic Supplier 14 | C18: FLEET | D18: FLEET | E18: Mid-performing fleet supplier with occasional quality issues

Sheet Supplier_Summary
A1: Supplier delivery, quality and spend summary
A2: SYNTHETIC DEMONSTRATION DATA - not real suppliers or real performance. Every metric is a live formula over Syn_Lines.
A3: Measured per PO line. Only due lines (not cancelled, promised on/before the as-of date) enter delivery rates; unreceived due lines count as late.
A4: Supplier ID | B4: Due lines | C4: OTIF lines | D4: OTIF rate | E4: On-time rate | F4: In-full rate | G4: Late lines | H4: Avg days late (all due lines) | I4: Completed lines | J4: Avg lead time (days) | K4: Lead-time SD (days) | L4: Received qty | M4: Rejected qty | N4: Reject rate | O4: Spend (ordered value) | P4: Value at contract price | Q4: PPV vs contract | R4: Share of total spend | S4: Open lines | T4: Overdue lines | U4: Overdue open value | V4: Due lines prior 12m | W4: OTIF prior 12m | X4: Due lines last 12m | Y4: OTIF last 12m | Z4: OTIF change (pts) | AA4: Lines closed short
A5: SUP-01 | B5: =COUNTIFS(Syn_Lines!$C$2:$C$4838,$A5,Syn_Lines!$U$2:$U$4838,1) | C5: =COUNTIFS(Syn_Lines!$C$2:$C$4838,$A5,Syn_Lines!$X$2:$X$4838,1) | D5: =IF(B5>0,C5/B5,"") | E5: =IF(B5>0,COUNTIFS(Syn_Lines!$C$2:$C$4838,$A5,Syn_Lines!$V$2:$V$4838,1)/B5,"") | F5: =IF(B5>0,COUNTIFS(Syn_Lines!$C$2:$C$4838,$A5,Syn_Lines!$W$2:$W$4838,1)/B5,"") | G5: =COUNTIFS(Syn_Lines!$C$2:$C$4838,$A5,Syn_Lines!$U$2:$U$4838,1,Syn_Lines!$AB$2:$AB$4838,">0") | H5: =IF(B5>0,AVERAGEIFS(Syn_Lines!$AB$2:$AB$4838,Syn_Lines!$C$2:$C$4838,$A5,Syn_Lines!$U$2:$U$4838,1),"") | I5: =COUNTIFS(Syn_Lines!$C$2:$C$4838,$A5,Syn_Lines!$Y$2:$Y$4838,1) | J5: =IF(I5>0,AVERAGEIFS(Syn_Lines!$AC$2:$AC$4838,Syn_Lines!$C$2:$C$4838,$A5,Syn_Lines!$Y$2:$Y$4838,1),"") | K5: =IF(I5>1,SQRT(MAX(0,(SUMIFS(Syn_Lines!$AD$2:$AD$4838,Syn_Lines!$C$2:$C$4838,$A5,Syn_Lines!$Y$2:$Y$4838,1)-I5*J5^2)/(I5-1))),"") | L5: =SUMIFS(Syn_Lines!$M$2:$M$4838,Syn_Lines!$C$2:$C$4838,$A5,Syn_Lines!$K$2:$K$4838,0) | M5: =SUMIFS(Syn_Lines!$O$2:$O$4838,Syn_Lines!$C$2:$C$4838,$A5,Syn_Lines!$K$2:$K$4838,0) | N5: =IF(L5>0,M5/L5,"") | O5: =SUMIFS(Syn_Lines!$S$2:$S$4838,Syn_Lines!$C$2:$C$4838,$A5,Syn_Lines!$K$2:$K$4838,0) | P5: =SUMIFS(Syn_Lines!$T$2:$T$4838,Syn_Lines!$C$2:$C$4838,$A5,Syn_Lines!$K$2:$K$4838,0) | Q5: =IF(P5>0,O5/P5-1,"") | R5: =O5/SUM($O$5:$O$18) | S5: =COUNTIFS(Syn_Lines!$C$2:$C$4838,$A5,Syn_Lines!$Z$2:$Z$4838,1) | T5: =COUNTIFS(Syn_Lines!$C$2:$C$4838,$A5,Syn_Lines!$AA$2:$AA$4838,1) | U5: =SUMIFS(Syn_Lines!$AE$2:$AE$4838,Syn_Lines!$C$2:$C$4838,$A5,Syn_Lines!$AA$2:$AA$4838,1) | V5: =COUNTIFS(Syn_Lines!$C$2:$C$4838,$A5,Syn_Lines!$U$2:$U$4838,1,Syn_Lines!$AF$2:$AF$4838,"prior_12m") | W5: =IF(V5>0,COUNTIFS(Syn_Lines!$C$2:$C$4838,$A5,Syn_Lines!$X$2:$X$4838,1,Syn_Lines!$AF$2:$AF$4838,"prior_12m")/V5,"") | X5: =COUNTIFS(Syn_Lines!$C$2:$C$4838,$A5,Syn_Lines!$U$2:$U$4838,1,Syn_Lines!$AF$2:$AF$4838,"last_12m") | Y5: =IF(X5>0,COUNTIFS(Syn_Lines!$C$2:$C$4838,$A5,Syn_Lines!$X$2:$X$4838,1,Syn_Lines!$AF$2:$AF$4838,"last_12m")/X5,"") | Z5: =IF(OR(W5="",Y5=""),"",Y5-W5) | AA5: =COUNTIFS(Syn_Lines!$C$2:$C$4838,$A5,Syn_Lines!$L$2:$L$4838,1)
A6: SUP-02 | B6: =COUNTIFS(Syn_Lines!$C$2:$C$4838,$A6,Syn_Lines!$U$2:$U$4838,1) | C6: =COUNTIFS(Syn_Lines!$C$2:$C$4838,$A6,Syn_Lines!$X$2:$X$4838,1) | D6: =IF(B6>0,C6/B6,"") | E6: =IF(B6>0,COUNTIFS(Syn_Lines!$C$2:$C$4838,$A6,Syn_Lines!$V$2:$V$4838,1)/B6,"") | F6: =IF(B6>0,COUNTIFS(Syn_Lines!$C$2:$C$4838,$A6,Syn_Lines!$W$2:$W$4838,1)/B6,"") | G6: =COUNTIFS(Syn_Lines!$C$2:$C$4838,$A6,Syn_Lines!$U$2:$U$4838,1,Syn_Lines!$AB$2:$AB$4838,">0") | H6: =IF(B6>0,AVERAGEIFS(Syn_Lines!$AB$2:$AB$4838,Syn_Lines!$C$2:$C$4838,$A6,Syn_Lines!$U$2:$U$4838,1),"") | I6: =COUNTIFS(Syn_Lines!$C$2:$C$4838,$A6,Syn_Lines!$Y$2:$Y$4838,1) | J6: =IF(I6>0,AVERAGEIFS(Syn_Lines!$AC$2:$AC$4838,Syn_Lines!$C$2:$C$4838,$A6,Syn_Lines!$Y$2:$Y$4838,1),"") | K6: =IF(I6>1,SQRT(MAX(0,(SUMIFS(Syn_Lines!$AD$2:$AD$4838,Syn_Lines!$C$2:$C$4838,$A6,Syn_Lines!$Y$2:$Y$4838,1)-I6*J6^2)/(I6-1))),"") | L6: =SUMIFS(Syn_Lines!$M$2:$M$4838,Syn_Lines!$C$2:$C$4838,$A6,Syn_Lines!$K$2:$K$4838,0) | M6: =SUMIFS(Syn_Lines!$O$2:$O$4838,Syn_Lines!$C$2:$C$4838,$A6,Syn_Lines!$K$2:$K$4838,0) | N6: =IF(L6>0,M6/L6,"") | O6: =SUMIFS(Syn_Lines!$S$2:$S$4838,Syn_Lines!$C$2:$C$4838,$A6,Syn_Lines!$K$2:$K$4838,0) | P6: =SUMIFS(Syn_Lines!$T$2:$T$4838,Syn_Lines!$C$2:$C$4838,$A6,Syn_Lines!$K$2:$K$4838,0) | Q6: =IF(P6>0,O6/P6-1,"") | R6: =O6/SUM($O$5:$O$18) | S6: =COUNTIFS(Syn_Lines!$C$2:$C$4838,$A6,Syn_Lines!$Z$2:$Z$4838,1) | T6: =COUNTIFS(Syn_Lines!$C$2:$C$4838,$A6,Syn_Lines!$AA$2:$AA$4838,1) | U6: =SUMIFS(Syn_Lines!$AE$2:$AE$4838,Syn_Lines!$C$2:$C$4838,$A6,Syn_Lines!$AA$2:$AA$4838,1) | V6: =COUNTIFS(Syn_Lines!$C$2:$C$4838,$A6,Syn_Lines!$U$2:$U$4838,1,Syn_Lines!$AF$2:$AF$4838,"prior_12m") | W6: =IF(V6>0,COUNTIFS(Syn_Lines!$C$2:$C$4838,$A6,Syn_Lines!$X$2:$X$4838,1,Syn_Lines!$AF$2:$AF$4838,"prior_12m")/V6,"") | X6: =COUNTIFS(Syn_Lines!$C$2:$C$4838,$A6,Syn_Lines!$U$2:$U$4838,1,Syn_Lines!$AF$2:$AF$4838,"last_12m") | Y6: =IF(X6>0,COUNTIFS(Syn_Lines!$C$2:$C$4838,$A6,Syn_Lines!$X$2:$X$4838,1,Syn_Lines!$AF$2:$AF$4838,"last_12m")/X6,"") | Z6: =IF(OR(W6="",Y6=""),"",Y6-W6) | AA6: =COUNTIFS(Syn_Lines!$C$2:$C$4838,$A6,Syn_Lines!$L$2:$L$4838,1)
A7: SUP-03 | B7: =COUNTIFS(Syn_Lines!$C$2:$C$4838,$A7,Syn_Lines!$U$2:$U$4838,1) | C7: =COUNTIFS(Syn_Lines!$C$2:$C$4838,$A7,Syn_Lines!$X$2:$X$4838,1) | D7: =IF(B7>0,C7/B7,"") | E7: =IF(B7>0,COUNTIFS(Syn_Lines!$C$2:$C$4838,$A7,Syn_Lines!$V$2:$V$4838,1)/B7,"") | F7: =IF(B7>0,COUNTIFS(Syn_Lines!$C$2:$C$4838,$A7,Syn_Lines!$W$2:$W$4838,1)/B7,"") | G7: =COUNTIFS(Syn_Lines!$C$2:$C$4838,$A7,Syn_Lines!$U$2:$U$4838,1,Syn_Lines!$AB$2:$AB$4838,">0") | H7: =IF(B7>0,AVERAGEIFS(Syn_Lines!$AB$2:$AB$4838,Syn_Lines!$C$2:$C$4838,$A7,Syn_Lines!$U$2:$U$4838,1),"") | I7: =COUNTIFS(Syn_Lines!$C$2:$C$4838,$A7,Syn_Lines!$Y$2:$Y$4838,1) | J7: =IF(I7>0,AVERAGEIFS(Syn_Lines!$AC$2:$AC$4838,Syn_Lines!$C$2:$C$4838,$A7,Syn_Lines!$Y$2:$Y$4838,1),"") | K7: =IF(I7>1,SQRT(MAX(0,(SUMIFS(Syn_Lines!$AD$2:$AD$4838,Syn_Lines!$C$2:$C$4838,$A7,Syn_Lines!$Y$2:$Y$4838,1)-I7*J7^2)/(I7-1))),"") | L7: =SUMIFS(Syn_Lines!$M$2:$M$4838,Syn_Lines!$C$2:$C$4838,$A7,Syn_Lines!$K$2:$K$4838,0) | M7: =SUMIFS(Syn_Lines!$O$2:$O$4838,Syn_Lines!$C$2:$C$4838,$A7,Syn_Lines!$K$2:$K$4838,0) | N7: =IF(L7>0,M7/L7,"") | O7: =SUMIFS(Syn_Lines!$S$2:$S$4838,Syn_Lines!$C$2:$C$4838,$A7,Syn_Lines!$K$2:$K$4838,0) | P7: =SUMIFS(Syn_Lines!$T$2:$T$4838,Syn_Lines!$C$2:$C$4838,$A7,Syn_Lines!$K$2:$K$4838,0) | Q7: =IF(P7>0,O7/P7-1,"") | R7: =O7/SUM($O$5:$O$18) | S7: =COUNTIFS(Syn_Lines!$C$2:$C$4838,$A7,Syn_Lines!$Z$2:$Z$4838,1) | T7: =COUNTIFS(Syn_Lines!$C$2:$C$4838,$A7,Syn_Lines!$AA$2:$AA$4838,1) | U7: =SUMIFS(Syn_Lines!$AE$2:$AE$4838,Syn_Lines!$C$2:$C$4838,$A7,Syn_Lines!$AA$2:$AA$4838,1) | V7: =COUNTIFS(Syn_Lines!$C$2:$C$4838,$A7,Syn_Lines!$U$2:$U$4838,1,Syn_Lines!$AF$2:$AF$4838,"prior_12m") | W7: =IF(V7>0,COUNTIFS(Syn_Lines!$C$2:$C$4838,$A7,Syn_Lines!$X$2:$X$4838,1,Syn_Lines!$AF$2:$AF$4838,"prior_12m")/V7,"") | X7: =COUNTIFS(Syn_Lines!$C$2:$C$4838,$A7,Syn_Lines!$U$2:$U$4838,1,Syn_Lines!$AF$2:$AF$4838,"last_12m") | Y7: =IF(X7>0,COUNTIFS(Syn_Lines!$C$2:$C$4838,$A7,Syn_Lines!$X$2:$X$4838,1,Syn_Lines!$AF$2:$AF$4838,"last_12m")/X7,"") | Z7: =IF(OR(W7="",Y7=""),"",Y7-W7) | AA7: =COUNTIFS(Syn_Lines!$C$2:$C$4838,$A7,Syn_Lines!$L$2:$L$4838,1)
A8: SUP-04 | B8: =COUNTIFS(Syn_Lines!$C$2:$C$4838,$A8,Syn_Lines!$U$2:$U$4838,1) | C8: =COUNTIFS(Syn_Lines!$C$2:$C$4838,$A8,Syn_Lines!$X$2:$X$4838,1) | D8: =IF(B8>0,C8/B8,"") | E8: =IF(B8>0,COUNTIFS(Syn_Lines!$C$2:$C$4838,$A8,Syn_Lines!$V$2:$V$4838,1)/B8,"") | F8: =IF(B8>0,COUNTIFS(Syn_Lines!$C$2:$C$4838,$A8,Syn_Lines!$W$2:$W$4838,1)/B8,"") | G8: =COUNTIFS(Syn_Lines!$C$2:$C$4838,$A8,Syn_Lines!$U$2:$U$4838,1,Syn_Lines!$AB$2:$AB$4838,">0") | H8: =IF(B8>0,AVERAGEIFS(Syn_Lines!$AB$2:$AB$4838,Syn_Lines!$C$2:$C$4838,$A8,Syn_Lines!$U$2:$U$4838,1),"") | I8: =COUNTIFS(Syn_Lines!$C$2:$C$4838,$A8,Syn_Lines!$Y$2:$Y$4838,1) | J8: =IF(I8>0,AVERAGEIFS(Syn_Lines!$AC$2:$AC$4838,Syn_Lines!$C$2:$C$4838,$A8,Syn_Lines!$Y$2:$Y$4838,1),"") | K8: =IF(I8>1,SQRT(MAX(0,(SUMIFS(Syn_Lines!$AD$2:$AD$4838,Syn_Lines!$C$2:$C$4838,$A8,Syn_Lines!$Y$2:$Y$4838,1)-I8*J8^2)/(I8-1))),"") | L8: =SUMIFS(Syn_Lines!$M$2:$M$4838,Syn_Lines!$C$2:$C$4838,$A8,Syn_Lines!$K$2:$K$4838,0) | M8: =SUMIFS(Syn_Lines!$O$2:$O$4838,Syn_Lines!$C$2:$C$4838,$A8,Syn_Lines!$K$2:$K$4838,0) | N8: =IF(L8>0,M8/L8,"") | O8: =SUMIFS(Syn_Lines!$S$2:$S$4838,Syn_Lines!$C$2:$C$4838,$A8,Syn_Lines!$K$2:$K$4838,0) | P8: =SUMIFS(Syn_Lines!$T$2:$T$4838,Syn_Lines!$C$2:$C$4838,$A8,Syn_Lines!$K$2:$K$4838,0) | Q8: =IF(P8>0,O8/P8-1,"") | R8: =O8/SUM($O$5:$O$18) | S8: =COUNTIFS(Syn_Lines!$C$2:$C$4838,$A8,Syn_Lines!$Z$2:$Z$4838,1) | T8: =COUNTIFS(Syn_Lines!$C$2:$C$4838,$A8,Syn_Lines!$AA$2:$AA$4838,1) | U8: =SUMIFS(Syn_Lines!$AE$2:$AE$4838,Syn_Lines!$C$2:$C$4838,$A8,Syn_Lines!$AA$2:$AA$4838,1) | V8: =COUNTIFS(Syn_Lines!$C$2:$C$4838,$A8,Syn_Lines!$U$2:$U$4838,1,Syn_Lines!$AF$2:$AF$4838,"prior_12m") | W8: =IF(V8>0,COUNTIFS(Syn_Lines!$C$2:$C$4838,$A8,Syn_Lines!$X$2:$X$4838,1,Syn_Lines!$AF$2:$AF$4838,"prior_12m")/V8,"") | X8: =COUNTIFS(Syn_Lines!$C$2:$C$4838,$A8,Syn_Lines!$U$2:$U$4838,1,Syn_Lines!$AF$2:$AF$4838,"last_12m") | Y8: =IF(X8>0,COUNTIFS(Syn_Lines!$C$2:$C$4838,$A8,Syn_Lines!$X$2:$X$4838,1,Syn_Lines!$AF$2:$AF$4838,"last_12m")/X8,"") | Z8: =IF(OR(W8="",Y8=""),"",Y8-W8) | AA8: =COUNTIFS(Syn_Lines!$C$2:$C$4838,$A8,Syn_Lines!$L$2:$L$4838,1)
A9: SUP-05 | B9: =COUNTIFS(Syn_Lines!$C$2:$C$4838,$A9,Syn_Lines!$U$2:$U$4838,1) | C9: =COUNTIFS(Syn_Lines!$C$2:$C$4838,$A9,Syn_Lines!$X$2:$X$4838,1) | D9: =IF(B9>0,C9/B9,"") | E9: =IF(B9>0,COUNTIFS(Syn_Lines!$C$2:$C$4838,$A9,Syn_Lines!$V$2:$V$4838,1)/B9,"") | F9: =IF(B9>0,COUNTIFS(Syn_Lines!$C$2:$C$4838,$A9,Syn_Lines!$W$2:$W$4838,1)/B9,"") | G9: =COUNTIFS(Syn_Lines!$C$2:$C$4838,$A9,Syn_Lines!$U$2:$U$4838,1,Syn_Lines!$AB$2:$AB$4838,">0") | H9: =IF(B9>0,AVERAGEIFS(Syn_Lines!$AB$2:$AB$4838,Syn_Lines!$C$2:$C$4838,$A9,Syn_Lines!$U$2:$U$4838,1),"") | I9: =COUNTIFS(Syn_Lines!$C$2:$C$4838,$A9,Syn_Lines!$Y$2:$Y$4838,1) | J9: =IF(I9>0,AVERAGEIFS(Syn_Lines!$AC$2:$AC$4838,Syn_Lines!$C$2:$C$4838,$A9,Syn_Lines!$Y$2:$Y$4838,1),"") | K9: =IF(I9>1,SQRT(MAX(0,(SUMIFS(Syn_Lines!$AD$2:$AD$4838,Syn_Lines!$C$2:$C$4838,$A9,Syn_Lines!$Y$2:$Y$4838,1)-I9*J9^2)/(I9-1))),"") | L9: =SUMIFS(Syn_Lines!$M$2:$M$4838,Syn_Lines!$C$2:$C$4838,$A9,Syn_Lines!$K$2:$K$4838,0) | M9: =SUMIFS(Syn_Lines!$O$2:$O$4838,Syn_Lines!$C$2:$C$4838,$A9,Syn_Lines!$K$2:$K$4838,0) | N9: =IF(L9>0,M9/L9,"") | O9: =SUMIFS(Syn_Lines!$S$2:$S$4838,Syn_Lines!$C$2:$C$4838,$A9,Syn_Lines!$K$2:$K$4838,0) | P9: =SUMIFS(Syn_Lines!$T$2:$T$4838,Syn_Lines!$C$2:$C$4838,$A9,Syn_Lines!$K$2:$K$4838,0) | Q9: =IF(P9>0,O9/P9-1,"") | R9: =O9/SUM($O$5:$O$18) | S9: =COUNTIFS(Syn_Lines!$C$2:$C$4838,$A9,Syn_Lines!$Z$2:$Z$4838,1) | T9: =COUNTIFS(Syn_Lines!$C$2:$C$4838,$A9,Syn_Lines!$AA$2:$AA$4838,1) | U9: =SUMIFS(Syn_Lines!$AE$2:$AE$4838,Syn_Lines!$C$2:$C$4838,$A9,Syn_Lines!$AA$2:$AA$4838,1) | V9: =COUNTIFS(Syn_Lines!$C$2:$C$4838,$A9,Syn_Lines!$U$2:$U$4838,1,Syn_Lines!$AF$2:$AF$4838,"prior_12m") | W9: =IF(V9>0,COUNTIFS(Syn_Lines!$C$2:$C$4838,$A9,Syn_Lines!$X$2:$X$4838,1,Syn_Lines!$AF$2:$AF$4838,"prior_12m")/V9,"") | X9: =COUNTIFS(Syn_Lines!$C$2:$C$4838,$A9,Syn_Lines!$U$2:$U$4838,1,Syn_Lines!$AF$2:$AF$4838,"last_12m") | Y9: =IF(X9>0,COUNTIFS(Syn_Lines!$C$2:$C$4838,$A9,Syn_Lines!$X$2:$X$4838,1,Syn_Lines!$AF$2:$AF$4838,"last_12m")/X9,"") | Z9: =IF(OR(W9="",Y9=""),"",Y9-W9) | AA9: =COUNTIFS(Syn_Lines!$C$2:$C$4838,$A9,Syn_Lines!$L$2:$L$4838,1)
A10: SUP-06 | B10: =COUNTIFS(Syn_Lines!$C$2:$C$4838,$A10,Syn_Lines!$U$2:$U$4838,1) | C10: =COUNTIFS(Syn_Lines!$C$2:$C$4838,$A10,Syn_Lines!$X$2:$X$4838,1) | D10: =IF(B10>0,C10/B10,"") | E10: =IF(B10>0,COUNTIFS(Syn_Lines!$C$2:$C$4838,$A10,Syn_Lines!$V$2:$V$4838,1)/B10,"") | F10: =IF(B10>0,COUNTIFS(Syn_Lines!$C$2:$C$4838,$A10,Syn_Lines!$W$2:$W$4838,1)/B10,"") | G10: =COUNTIFS(Syn_Lines!$C$2:$C$4838,$A10,Syn_Lines!$U$2:$U$4838,1,Syn_Lines!$AB$2:$AB$4838,">0") | H10: =IF(B10>0,AVERAGEIFS(Syn_Lines!$AB$2:$AB$4838,Syn_Lines!$C$2:$C$4838,$A10,Syn_Lines!$U$2:$U$4838,1),"") | I10: =COUNTIFS(Syn_Lines!$C$2:$C$4838,$A10,Syn_Lines!$Y$2:$Y$4838,1) | J10: =IF(I10>0,AVERAGEIFS(Syn_Lines!$AC$2:$AC$4838,Syn_Lines!$C$2:$C$4838,$A10,Syn_Lines!$Y$2:$Y$4838,1),"") | K10: =IF(I10>1,SQRT(MAX(0,(SUMIFS(Syn_Lines!$AD$2:$AD$4838,Syn_Lines!$C$2:$C$4838,$A10,Syn_Lines!$Y$2:$Y$4838,1)-I10*J10^2)/(I10-1))),"") | L10: =SUMIFS(Syn_Lines!$M$2:$M$4838,Syn_Lines!$C$2:$C$4838,$A10,Syn_Lines!$K$2:$K$4838,0) | M10: =SUMIFS(Syn_Lines!$O$2:$O$4838,Syn_Lines!$C$2:$C$4838,$A10,Syn_Lines!$K$2:$K$4838,0) | N10: =IF(L10>0,M10/L10,"") | O10: =SUMIFS(Syn_Lines!$S$2:$S$4838,Syn_Lines!$C$2:$C$4838,$A10,Syn_Lines!$K$2:$K$4838,0) | P10: =SUMIFS(Syn_Lines!$T$2:$T$4838,Syn_Lines!$C$2:$C$4838,$A10,Syn_Lines!$K$2:$K$4838,0) | Q10: =IF(P10>0,O10/P10-1,"") | R10: =O10/SUM($O$5:$O$18) | S10: =COUNTIFS(Syn_Lines!$C$2:$C$4838,$A10,Syn_Lines!$Z$2:$Z$4838,1) | T10: =COUNTIFS(Syn_Lines!$C$2:$C$4838,$A10,Syn_Lines!$AA$2:$AA$4838,1) | U10: =SUMIFS(Syn_Lines!$AE$2:$AE$4838,Syn_Lines!$C$2:$C$4838,$A10,Syn_Lines!$AA$2:$AA$4838,1) | V10: =COUNTIFS(Syn_Lines!$C$2:$C$4838,$A10,Syn_Lines!$U$2:$U$4838,1,Syn_Lines!$AF$2:$AF$4838,"prior_12m") | W10: =IF(V10>0,COUNTIFS(Syn_Lines!$C$2:$C$4838,$A10,Syn_Lines!$X$2:$X$4838,1,Syn_Lines!$AF$2:$AF$4838,"prior_12m")/V10,"") | X10: =COUNTIFS(Syn_Lines!$C$2:$C$4838,$A10,Syn_Lines!$U$2:$U$4838,1,Syn_Lines!$AF$2:$AF$4838,"last_12m") | Y10: =IF(X10>0,COUNTIFS(Syn_Lines!$C$2:$C$4838,$A10,Syn_Lines!$X$2:$X$4838,1,Syn_Lines!$AF$2:$AF$4838,"last_12m")/X10,"") | Z10: =IF(OR(W10="",Y10=""),"",Y10-W10) | AA10: =COUNTIFS(Syn_Lines!$C$2:$C$4838,$A10,Syn_Lines!$L$2:$L$4838,1)
A11: SUP-07 | B11: =COUNTIFS(Syn_Lines!$C$2:$C$4838,$A11,Syn_Lines!$U$2:$U$4838,1) | C11: =COUNTIFS(Syn_Lines!$C$2:$C$4838,$A11,Syn_Lines!$X$2:$X$4838,1) | D11: =IF(B11>0,C11/B11,"") | E11: =IF(B11>0,COUNTIFS(Syn_Lines!$C$2:$C$4838,$A11,Syn_Lines!$V$2:$V$4838,1)/B11,"") | F11: =IF(B11>0,COUNTIFS(Syn_Lines!$C$2:$C$4838,$A11,Syn_Lines!$W$2:$W$4838,1)/B11,"") | G11: =COUNTIFS(Syn_Lines!$C$2:$C$4838,$A11,Syn_Lines!$U$2:$U$4838,1,Syn_Lines!$AB$2:$AB$4838,">0") | H11: =IF(B11>0,AVERAGEIFS(Syn_Lines!$AB$2:$AB$4838,Syn_Lines!$C$2:$C$4838,$A11,Syn_Lines!$U$2:$U$4838,1),"") | I11: =COUNTIFS(Syn_Lines!$C$2:$C$4838,$A11,Syn_Lines!$Y$2:$Y$4838,1) | J11: =IF(I11>0,AVERAGEIFS(Syn_Lines!$AC$2:$AC$4838,Syn_Lines!$C$2:$C$4838,$A11,Syn_Lines!$Y$2:$Y$4838,1),"") | K11: =IF(I11>1,SQRT(MAX(0,(SUMIFS(Syn_Lines!$AD$2:$AD$4838,Syn_Lines!$C$2:$C$4838,$A11,Syn_Lines!$Y$2:$Y$4838,1)-I11*J11^2)/(I11-1))),"") | L11: =SUMIFS(Syn_Lines!$M$2:$M$4838,Syn_Lines!$C$2:$C$4838,$A11,Syn_Lines!$K$2:$K$4838,0) | M11: =SUMIFS(Syn_Lines!$O$2:$O$4838,Syn_Lines!$C$2:$C$4838,$A11,Syn_Lines!$K$2:$K$4838,0) | N11: =IF(L11>0,M11/L11,"") | O11: =SUMIFS(Syn_Lines!$S$2:$S$4838,Syn_Lines!$C$2:$C$4838,$A11,Syn_Lines!$K$2:$K$4838,0) | P11: =SUMIFS(Syn_Lines!$T$2:$T$4838,Syn_Lines!$C$2:$C$4838,$A11,Syn_Lines!$K$2:$K$4838,0) | Q11: =IF(P11>0,O11/P11-1,"") | R11: =O11/SUM($O$5:$O$18) | S11: =COUNTIFS(Syn_Lines!$C$2:$C$4838,$A11,Syn_Lines!$Z$2:$Z$4838,1) | T11: =COUNTIFS(Syn_Lines!$C$2:$C$4838,$A11,Syn_Lines!$AA$2:$AA$4838,1) | U11: =SUMIFS(Syn_Lines!$AE$2:$AE$4838,Syn_Lines!$C$2:$C$4838,$A11,Syn_Lines!$AA$2:$AA$4838,1) | V11: =COUNTIFS(Syn_Lines!$C$2:$C$4838,$A11,Syn_Lines!$U$2:$U$4838,1,Syn_Lines!$AF$2:$AF$4838,"prior_12m") | W11: =IF(V11>0,COUNTIFS(Syn_Lines!$C$2:$C$4838,$A11,Syn_Lines!$X$2:$X$4838,1,Syn_Lines!$AF$2:$AF$4838,"prior_12m")/V11,"") | X11: =COUNTIFS(Syn_Lines!$C$2:$C$4838,$A11,Syn_Lines!$U$2:$U$4838,1,Syn_Lines!$AF$2:$AF$4838,"last_12m") | Y11: =IF(X11>0,COUNTIFS(Syn_Lines!$C$2:$C$4838,$A11,Syn_Lines!$X$2:$X$4838,1,Syn_Lines!$AF$2:$AF$4838,"last_12m")/X11,"") | Z11: =IF(OR(W11="",Y11=""),"",Y11-W11) | AA11: =COUNTIFS(Syn_Lines!$C$2:$C$4838,$A11,Syn_Lines!$L$2:$L$4838,1)
A12: SUP-08 | B12: =COUNTIFS(Syn_Lines!$C$2:$C$4838,$A12,Syn_Lines!$U$2:$U$4838,1) | C12: =COUNTIFS(Syn_Lines!$C$2:$C$4838,$A12,Syn_Lines!$X$2:$X$4838,1) | D12: =IF(B12>0,C12/B12,"") | E12: =IF(B12>0,COUNTIFS(Syn_Lines!$C$2:$C$4838,$A12,Syn_Lines!$V$2:$V$4838,1)/B12,"") | F12: =IF(B12>0,COUNTIFS(Syn_Lines!$C$2:$C$4838,$A12,Syn_Lines!$W$2:$W$4838,1)/B12,"") | G12: =COUNTIFS(Syn_Lines!$C$2:$C$4838,$A12,Syn_Lines!$U$2:$U$4838,1,Syn_Lines!$AB$2:$AB$4838,">0") | H12: =IF(B12>0,AVERAGEIFS(Syn_Lines!$AB$2:$AB$4838,Syn_Lines!$C$2:$C$4838,$A12,Syn_Lines!$U$2:$U$4838,1),"") | I12: =COUNTIFS(Syn_Lines!$C$2:$C$4838,$A12,Syn_Lines!$Y$2:$Y$4838,1) | J12: =IF(I12>0,AVERAGEIFS(Syn_Lines!$AC$2:$AC$4838,Syn_Lines!$C$2:$C$4838,$A12,Syn_Lines!$Y$2:$Y$4838,1),"") | K12: =IF(I12>1,SQRT(MAX(0,(SUMIFS(Syn_Lines!$AD$2:$AD$4838,Syn_Lines!$C$2:$C$4838,$A12,Syn_Lines!$Y$2:$Y$4838,1)-I12*J12^2)/(I12-1))),"") | L12: =SUMIFS(Syn_Lines!$M$2:$M$4838,Syn_Lines!$C$2:$C$4838,$A12,Syn_Lines!$K$2:$K$4838,0) | M12: =SUMIFS(Syn_Lines!$O$2:$O$4838,Syn_Lines!$C$2:$C$4838,$A12,Syn_Lines!$K$2:$K$4838,0) | N12: =IF(L12>0,M12/L12,"") | O12: =SUMIFS(Syn_Lines!$S$2:$S$4838,Syn_Lines!$C$2:$C$4838,$A12,Syn_Lines!$K$2:$K$4838,0) | P12: =SUMIFS(Syn_Lines!$T$2:$T$4838,Syn_Lines!$C$2:$C$4838,$A12,Syn_Lines!$K$2:$K$4838,0) | Q12: =IF(P12>0,O12/P12-1,"") | R12: =O12/SUM($O$5:$O$18) | S12: =COUNTIFS(Syn_Lines!$C$2:$C$4838,$A12,Syn_Lines!$Z$2:$Z$4838,1) | T12: =COUNTIFS(Syn_Lines!$C$2:$C$4838,$A12,Syn_Lines!$AA$2:$AA$4838,1) | U12: =SUMIFS(Syn_Lines!$AE$2:$AE$4838,Syn_Lines!$C$2:$C$4838,$A12,Syn_Lines!$AA$2:$AA$4838,1) | V12: =COUNTIFS(Syn_Lines!$C$2:$C$4838,$A12,Syn_Lines!$U$2:$U$4838,1,Syn_Lines!$AF$2:$AF$4838,"prior_12m") | W12: =IF(V12>0,COUNTIFS(Syn_Lines!$C$2:$C$4838,$A12,Syn_Lines!$X$2:$X$4838,1,Syn_Lines!$AF$2:$AF$4838,"prior_12m")/V12,"") | X12: =COUNTIFS(Syn_Lines!$C$2:$C$4838,$A12,Syn_Lines!$U$2:$U$4838,1,Syn_Lines!$AF$2:$AF$4838,"last_12m") | Y12: =IF(X12>0,COUNTIFS(Syn_Lines!$C$2:$C$4838,$A12,Syn_Lines!$X$2:$X$4838,1,Syn_Lines!$AF$2:$AF$4838,"last_12m")/X12,"") | Z12: =IF(OR(W12="",Y12=""),"",Y12-W12) | AA12: =COUNTIFS(Syn_Lines!$C$2:$C$4838,$A12,Syn_Lines!$L$2:$L$4838,1)
